Workbook

Sheet 0_Dashboard_Toggles
B1: Project Harmony – Spotify Technology S.A. Take-Private LBO | J1: Master check: | K1: =$D$49 -> OK
B2: € millions unless stated | Close 31-Dec-2026 | 7-year hold to FY2033E | Inputs blue, formulas black, cross-sheet links green, checks red
B3: GLOBAL CONTROLS
B4: Scenario selector | C4: Base | D4: Data validation: Base / Upside / Downside
B5: Scenario index (INDEX/MATCH) | C5: =MATCH(C4,$E$23:$G$23,0) -> 1 | D5: Drives column H of the scenario matrix
B7: Offer premium to unaffected price | C7: 0.3 | D7: IC case 30%
B8: Unaffected share price (USD) | C8: 490.3 | D8: SPOT Sep-2026 month-end close
B9: EUR per USD | C9: 0.8756 | D9: Spotify Q2'26 6-K guidance rate (30-Jun-2026)
B10: Interest circularity toggle (1 = avg balances, 0 = opening) | C10: 0 | D10: Shipped at 0 (opening-balance interest, fully balanced). Set 1 for average-balance interest – iterative calc is pre-enabled; or run macro SolveInterestCircularity. 0 is also the circuit breaker.
B11: Cash sweep toggle (1 = on) | C11: 1
B12: Cash sweep % of excess cash | C12: 1
B13: Minimum cash balance | C13: 1500 | D13: Buffer vs. €2.6bn accrued royalties (negative working capital)
B14: Entry gross leverage (x FY26E Adj. EBITDA) | C14: 6
B15: Advisory & legal fees (% of EV) | C15: 0.0035 | D15: Expensed at close
B16: Financing fees (% of funded debt) | C16: 0.0225 | D16: Capitalised, amortised over 7 years
B17: TLB OID (% of TLB) | C17: 0.005 | D17: Capitalised with financing fees
B18: Cash tax rate | C18: 0.2494 | D18: Luxembourg City combined CIT + MBT
B19: ATAD interest cap (% of tax-EBITDA) | C19: 0.3 | D19: Lux & Sweden implement ATAD Art. 4; €3m de minimis
B20: Management Incentive Plan (% of equity gain) | C20: 0.08
B21: Exit multiple override (blank = scenario value) | D21: Type a value to override
B22: Live exit EV / EBITDA multiple | C22: =IF(C21="",H35,C21) -> 22
B23: SCENARIO MATRIX | E23: Base | F23: Upside | G23: Downside | H23: Live
B24: Premium sub growth FY27E (fades linearly to FY33E) | E24: 0.075 | F24: 0.09 | G24: 0.05 | H24: =INDEX(E24:G24,1,$C$5) -> 0.075
B25: Premium sub growth FY33E | E25: 0.04 | F25: 0.05 | G25: 0.03 | H25: =INDEX(E25:G25,1,$C$5) -> 0.04
B26: Premium ARPU growth p.a. | E26: 0.04 | F26: 0.05 | G26: 0.025 | H26: =INDEX(E26:G26,1,$C$5) -> 0.04
B27: Monthly Premium churn (base level) | E27: 0.02 | F27: 0.018 | G27: 0.024 | H27: =INDEX(E27:G27,1,$C$5) -> 0.02
B28: Ad-Supported revenue growth p.a. | E28: 0.08 | F28: 0.12 | G28: 0.03 | H28: =INDEX(E28:G28,1,$C$5) -> 0.08
B29: Music royalty rate step-down p.a. (bps of Premium rev.) | E29: 70 | F29: 110 | G29: 15 | H29: =INDEX(E29:G29,1,$C$5) -> 70
B30: Ad-Supported gross margin FY33E | E30: 0.3 | F30: 0.34 | G30: 0.22 | H30: =INDEX(E30:G30,1,$C$5) -> 0.3
B31: R&D % revenue (reached FY29E) | E31: 0.07 | F31: 0.065 | G31: 0.078 | H31: =INDEX(E31:G31,1,$C$5) -> 0.07
B32: S&M % revenue (reached FY29E) | E32: 0.07 | F32: 0.066 | G32: 0.076 | H32: =INDEX(E32:G32,1,$C$5) -> 0.07
B33: G&A % revenue (reached FY29E) | E33: 0.025 | F33: 0.024 | G33: 0.026 | H33: =INDEX(E33:G33,1,$C$5) -> 0.025
B34: EURIBOR shift vs. forward curve (bps) | E34: 0 | F34: -25 | G34: 100 | H34: =INDEX(E34:G34,1,$C$5) -> 0
B35: Exit EV / EBITDA multiple | E35: 22 | F35: 25 | G35: 16 | H35: =INDEX(E35:G35,1,$C$5) -> 22
B36: % of SBC converted to cash compensation post-close | E36: 0.5 | F36: 0.4 | G36: 0.6 | H36: =INDEX(E36:G36,1,$C$5) -> 0.5
B37: Dividend recap switch (set in 4_Debt_Schedule!C73 – default OFF) | C37: ='4_Debt_Schedule'!C73 -> 0 | D37: Base case is unchanged when 0. See 6_IC_Analysis section C for recap results.
B39: AUTOMATED AUDIT CHECKS (must all be zero)
B40: Balance sheet balances (Σ|Assets − L&E|) | D40: =SUMPRODUCT(ABS('3_Financial_Statements'!E66:L66)) -> 0
B41: Cash flow closing cash = BS cash | D41: =SUMPRODUCT(ABS('3_Financial_Statements'!F44:L44-'3_Financial_Statements'!F47:L47)) -> 0
B42: Sources = Uses | D42: =ABS('1_Transaction_Summary'!C52) -> 0
...

Sheet 1_Transaction_Summary
B1: 1 | Transaction Summary – Purchase Price Bridge & Sources and Uses | J1: Master check: | K1: ='0_Dashboard_Toggles'!$D$49 -> OK
B2: Share data: Spotify Q2 2026 Form 6-K (Ex. 99.1, filed 4-Aug-2026) EPS note; balance sheet at 30-Jun-2026
B4: PURCHASE PRICE BRIDGE
B5: Unaffected share price (USD) | C5: ='0_Dashboard_Toggles'!C8 -> 490.3
B6: Offer price per share (USD) | C6: =C5*(1+'0_Dashboard_Toggles'!C7) -> 637.39
B7: EUR per USD | C7: ='0_Dashboard_Toggles'!C9 -> 0.8756
B8: Offer price per share (EUR) | C8: =C6*C7 -> 558.09868
B10: Basic shares outstanding (m) | C10: 205.78824
B11: Option tranches (Treasury Stock Method) | C11: Options (m) | D11: Strike (USD) | E11: TSM shares (m) | F11: Cash-out (€m)
B12: Tranche 1 (legacy grants) | C12: 3 | D12: 150 | E12: =IF(D12<$C$6,C12-C12*D12/$C$6,0) -> 2.2939958 | F12: =IF(D12<$C$6,C12*($C$6-D12)*$C$7,0) -> 1280.2761
B13: Tranche 2 | C13: 1 | D13: 350 | E13: =IF(D13<$C$6,C13-C13*D13/$C$6,0) -> 0.45088564 | F13: =IF(D13<$C$6,C13*($C$6-D13)*$C$7,0) -> 251.63868
B14: Tranche 3 (recent grants) | C14: 0.6 | D14: 480 | E14: =IF(D14<$C$6,C14-C14*D14/$C$6,0) -> 0.14815733 | F14: =IF(D14<$C$6,C14*($C$6-D14)*$C$7,0) -> 82.68641
B15: Total options | C15: =SUM(C12:C14) -> 4.6 | E15: =SUM(E12:E14) -> 2.8930388 | F15: =SUM(F12:F14) -> 1614.6011
B16: Unvested RSUs (m) | C16: 0.674073
B17: Fully diluted shares outstanding (m) | C17: =C10+E15+C16 -> 209.35535
B19: Equity purchase price (incl. option cash-out) | C19: =C17*C8 -> 116840.95
B20: Less: cash and cash equivalents | C20: -5938 | G20: 6-K BS 30-Jun-26
B21: Less: short-term investments | C21: -3450 | G21: 6-K BS 30-Jun-26
B22: Less: long-term investments (non-operating) | C22: -1118 | G22: 6-K BS; incl. TME stake
B23: Plus: lease liabilities (IFRS 16) | C23: 470 | G23: €404m non-current + c.€66m current (E)
B24: Plus: financial debt | C24: 0 | G24: Exchangeable Notes repaid Q1'26 (€1,304m)
B25: Enterprise value | C25: =SUM(C19:C24) -> 106804.95
B27: FY26E Adj. EBITDA | C27: ='2_Operating_Build'!E79 -> 3282.595
B28: EV / FY26E Adj. EBITDA | C28: =C25/C27 -> 32.536742
B29: EV / LTM Adj. EBITDA (LTM Q2'26: €3,070m est.) | C29: =C25/D29 -> 34.789885 | D29: 3070
B30: EV / LTM FCF (LTM Q2'26: €3,261m, 6-K) | C30: =C25/D30 -> 32.752207 | D30: 3261
B31: Memo: unaffected EV / FY26E EBITDA | C31: =(C17*C5*C7+SUM(C20:C24))/C27 -> 24.322724
B32: Memo: EV / FY26E EBITDA on post-close SBC definition (only non-cash SBC added back) | C32: =C25/(C27-'2_Operating_Build'!E76*'0_Dashboard_Toggles'!H36) -> 34.207302
B33: SOURCES & USES | C33: €m | D33: % total | E33: x EBITDA
B34: Uses
B35: Equity purchase price | C35: =C19 -> 116840.95 | D35: =C35/$C$39 -> 0.9926932
B36: Advisory & legal fees | C36: ='0_Dashboard_Toggles'!C15*C25 -> 373.81731 | D36: =C36/$C$39 -> 0.0031759919
B37: Financing fees | C37: ='0_Dashboard_Toggles'!C16*C47 -> 443.25 | D37: =C37/$C$39 -> 0.0037658995
B38: TLB original issue discount | C38: ='0_Dashboard_Toggles'!C17*C43 -> 42.95 | D38: =C38/$C$39 -> 0.0003649078
B39: Total uses | C39: =SUM(C35:C38) -> 117700.96
B41: Sources | F41: Tranche split
B42: Senior Secured Term Loan A (E+325, 7-yr amortising) | C42: =ROUND(C47*F42,-1) -> 4040 | D42: =C42/$C$51 -> 0.034324273 | E42: =C42/$C$27 -> 1.2307336 | F42: 0.205
B43: Senior Term Loan B (E+400, 8-yr bullet) | C43: =ROUND(C47*F43,-1) -> 8590 | D43: =C43/$C$51 -> 0.07298156 | E43: =C43/$C$27 -> 2.6168321 | F43: 0.436
B44: Senior Unsecured Notes (7.50% fixed, 8-yr) | C44: =C47-C42-C43 -> 7070 | D44: =C44/$C$51 -> 0.060067477 | E44: =C44/$C$27 -> 2.1537838 | F44: =1-F42-F43 -> 0.359
B45: Revolving Credit Facility (€500m, undrawn at close) | C45: 0 | D45: =C45/$C$51 -> 0 | E45: =C45/$C$27 -> 0
...

Sheet 2_Operating_Build
B1: 2 | Operating Build – Segment Revenue, Royalties & OpEx | J1: Master check: | K1: ='0_Dashboard_Toggles'!$D$49 -> OK
B2: FY26E = Q1–Q2 actuals (6-K) + Q3 guidance + Q4E | Regional split estimated except Europe (36% of subs, disclosed) | E2: Close / LTM
B3: Fiscal year (Dec YE) | E3: 2026 | F3: 2027 | G3: 2028 | H3: 2029 | I3: 2030 | J3: 2031 | K3: 2032 | L3: 2033
B4: Period (t) | E4: 0 | F4: 1 | G4: 2 | H4: 3 | I4: 4 | J4: 5 | K4: 6 | L4: 7
B5: PREMIUM SUBSCRIBER DRIVERS
B6: Scenario base subscriber growth (linear fade) | C6: % | F6: ='0_Dashboard_Toggles'!$H$24+('0_Dashboard_Toggles'!$H$25-'0_Dashboard_Toggles'!$H$24)*(F$4-1)/6 -> 0.075 | G6: ='0_Dashboard_Toggles'!$H$24+('0_Dashboard_Toggles'!$H$25-'0_Dashboard_Toggles'!$H$24)*(G$4-1)/6 -> 0.069166667 | H6: ='0_Dashboard_Toggles'!$H$24+('0_Dashboard_Toggles'!$H$25-'0_Dashboard_Toggles'!$H$24)*(H$4-1)/6 -> 0.063333333 | I6: ='0_Dashboard_Toggles'!$H$24+('0_Dashboard_Toggles'!$H$25-'0_Dashboard_Toggles'!$H$24)*(I$4-1)/6 -> 0.0575 | J6: ='0_Dashboard_Toggles'!$H$24+('0_Dashboard_Toggles'!$H$25-'0_Dashboard_Toggles'!$H$24)*(J$4-1)/6 -> 0.051666667 | K6: ='0_Dashboard_Toggles'!$H$24+('0_Dashboard_Toggles'!$H$25-'0_Dashboard_Toggles'!$H$24)*(K$4-1)/6 -> 0.045833333 | L6: ='0_Dashboard_Toggles'!$H$24+('0_Dashboard_Toggles'!$H$25-'0_Dashboard_Toggles'!$H$24)*(L$4-1)/6 -> 0.04
B7: Premium ARPU growth | C7: % | F7: ='0_Dashboard_Toggles'!$H$26 -> 0.04 | G7: ='0_Dashboard_Toggles'!$H$26 -> 0.04 | H7: ='0_Dashboard_Toggles'!$H$26 -> 0.04 | I7: ='0_Dashboard_Toggles'!$H$26 -> 0.04 | J7: ='0_Dashboard_Toggles'!$H$26 -> 0.04 | K7: ='0_Dashboard_Toggles'!$H$26 -> 0.04 | L7: ='0_Dashboard_Toggles'!$H$26 -> 0.04
B8: Monthly churn incl. price elasticity | C8: % | E8: ='0_Dashboard_Toggles'!$H$27 -> 0.02 | F8: ='0_Dashboard_Toggles'!$H$27+$E$9*MAX(0,F7-$E$10) -> 0.0205 | G8: ='0_Dashboard_Toggles'!$H$27+$E$9*MAX(0,G7-$E$10) -> 0.0205 | H8: ='0_Dashboard_Toggles'!$H$27+$E$9*MAX(0,H7-$E$10) -> 0.0205 | I8: ='0_Dashboard_Toggles'!$H$27+$E$9*MAX(0,I7-$E$10) -> 0.0205 | J8: ='0_Dashboard_Toggles'!$H$27+$E$9*MAX(0,J7-$E$10) -> 0.0205 | K8: ='0_Dashboard_Toggles'!$H$27+$E$9*MAX(0,K7-$E$10) -> 0.0205 | L8: ='0_Dashboard_Toggles'!$H$27+$E$9*MAX(0,L7-$E$10) -> 0.0205
B9: Elasticity: Δ monthly churn per 1.0 of ARPU growth above neutral | C9: x | D9: Input | E9: 0.05
B10: Price-neutral ARPU growth | C10: % | D10: Input | E10: 0.03
B11: Incremental annual churn vs. base (drag on net adds) | C11: % | F11: =(1-(1-F8)^12)-(1-(1-'0_Dashboard_Toggles'!$H$27)^12) -> 0.0047909293 | G11: =(1-(1-G8)^12)-(1-(1-'0_Dashboard_Toggles'!$H$27)^12) -> 0.0047909293 | H11: =(1-(1-H8)^12)-(1-(1-'0_Dashboard_Toggles'!$H$27)^12) -> 0.0047909293 | I11: =(1-(1-I8)^12)-(1-(1-'0_Dashboard_Toggles'!$H$27)^12) -> 0.0047909293 | J11: =(1-(1-J8)^12)-(1-(1-'0_Dashboard_Toggles'!$H$27)^12) -> 0.0047909293 | K11: =(1-(1-K8)^12)-(1-(1-'0_Dashboard_Toggles'!$H$27)^12) -> 0.0047909293 | L11: =(1-(1-L8)^12)-(1-(1-'0_Dashboard_Toggles'!$H$27)^12) -> 0.0047909293
B13: North America | C13: Growth spread | D13: -0.025
B14: Closing Premium subs | C14: m | E14: 74 | F14: =E14*(1+F$6+$D$13-F$11) -> 77.345471 | G14: =F14*(1+G$6+$D$13-G$11) -> 80.391006 | H14: =G14*(1+H$6+$D$13-H$11) -> 83.087514 | I14: =H14*(1+I$6+$D$13-I$11) -> 85.389792 | J14: =I14*(1+J$6+$D$13-J$11) -> 87.257756 | K14: =J14*(1+K$6+$D$13-K$11) -> 88.65758 | L14: =K14*(1+L$6+$D$13-L$11) -> 89.562692
B15: Average subs | C15: m | F15: =AVERAGE(E14,F14) -> 75.672736 | G15: =AVERAGE(F14,G14) -> 78.868239 | H15: =AVERAGE(G14,H14) -> 81.73926 | I15: =AVERAGE(H14,I14) -> 84.238653 | J15: =AVERAGE(I14,J14) -> 86.323774 | K15: =AVERAGE(J14,K14) -> 87.957668 | L15: =AVERAGE(K14,L14) -> 89.110136
B16: Monthly ARPU | C16: € | E16: 8.95 | F16: =E16*(1+F$7) -> 9.308 | G16: =F16*(1+G$7) -> 9.68032 | H16: =G16*(1+H$7) -> 10.067533 | I16: =H16*(1+I$7) -> 10.470234 | J16: =I16*(1+J$7) -> 10.889043 | K16: =J16*(1+K$7) -> 11.324605 | L16: =K16*(1+L$7) -> 11.777589
B17: Premium revenue | C17: €m | F17: =F15*F16*12 -> 8452.3419 | G17: =G15*G16*12 -> 9161.6375 | H17: =H15*H16*12 -> 9874.9522 | I17: =I15*I16*12 -> 10583.981 | J17: =J15*J16*12 -> 11279.8 | K17: =K15*K16*12 -> 11953.03 | L17: =L15*L16*12 -> 12594.031
B18: Europe | C18: Growth spread | D18: -0.01
B19: Closing Premium subs | C19: m | E19: 111 | F19: =E19*(1+F$6+$D$18-F$11) -> 117.68321 | G19: =F19*(1+G$6+$D$18-G$11) -> 124.08232 | H19: =G19*(1+H$6+$D$18-H$11) -> 130.10557 | I19: =H19*(1+I$6+$D$18-I$11) -> 135.66226 | J19: =I19*(1+J$6+$D$18-J$11) -> 140.66491 | K19: =J19*(1+K$6+$D$18-K$11) -> 145.03148 | L19: =K19*(1+L$6+$D$18-L$11) -> 148.68759
B20: Average subs | C20: m | F20: =AVERAGE(E19,F19) -> 114.3416 | G20: =AVERAGE(F19,G19) -> 120.88276 | H20: =AVERAGE(G19,H19) -> 127.09395 | I20: =AVERAGE(H19,I19) -> 132.88392 | J20: =AVERAGE(I19,J19) -> 138.16358 | K20: =AVERAGE(J19,K19) -> 142.84819 | L20: =AVERAGE(K19,L19) -> 146.85954
B21: Monthly ARPU | C21: € | E21: 5.25 | F21: =E21*(1+F$7) -> 5.46 | G21: =F21*(1+G$7) -> 5.6784 | H21: =G21*(1+H$7) -> 5.905536 | I21: =H21*(1+I$7) -> 6.1417574 | J21: =I21*(1+J$7) -> 6.3874277 | K21: =J21*(1+K$7) -> 6.6429248 | L21: =K21*(1+L$7) -> 6.9086418
B22: Premium revenue | C22: €m | F22: =F20*F21*12 -> 7491.6619 | G22: =G20*G21*12 -> 8237.0481 | H22: =H20*H21*12 -> 9006.6944 | I22: =I20*I21*12 -> 9793.6894 | J22: =J20*J21*12 -> 10590.119 | K22: =K20*K21*12 -> 11387.158 | L22: =L20*L21*12 -> 12175.199
B23: Latin America | C23: Growth spread | D23: 0.01
B24: Closing Premium subs | C24: m | E24: 68 | F24: =E24*(1+F$6+$D$23-F$11) -> 73.454217 | G24: =F24*(1+G$6+$D$23-G$11) -> 78.917428 | H24: =G24*(1+H$6+$D$23-H$11) -> 84.326619 | I24: =H24*(1+I$6+$D$23-I$11) -> 89.614662 | J24: =I24*(1+J$6+$D$23-J$11) -> 94.711562 | K24: =J24*(1+K$6+$D$23-K$11) -> 99.545868 | L24: =K24*(1+L$6+$D$23-L$11) -> 104.04624
B25: Average subs | C25: m | F25: =AVERAGE(E24,F24) -> 70.727108 | G25: =AVERAGE(F24,G24) -> 76.185823 | H25: =AVERAGE(G24,H24) -> 81.622023 | I25: =AVERAGE(H24,I24) -> 86.970641 | J25: =AVERAGE(I24,J24) -> 92.163112 | K25: =AVERAGE(J24,K24) -> 97.128715 | L25: =AVERAGE(K24,L24) -> 101.79606
B26: Monthly ARPU | C26: € | E26: 2.3 | F26: =E26*(1+F$7) -> 2.392 | G26: =F26*(1+G$7) -> 2.48768 | H26: =G26*(1+H$7) -> 2.5871872 | I26: =H26*(1+I$7) -> 2.6906747 | J26: =I26*(1+J$7) -> 2.7983017 | K26: =J26*(1+K$7) -> 2.9102337 | L26: =K26*(1+L$7) -> 3.0266431
B27: Premium revenue | C27: €m | F27: =F25*F26*12 -> 2030.1509 | G27: =G25*G26*12 -> 2274.3114 | H27: =H25*H26*12 -> 2534.0575 | I27: =I25*I26*12 -> 2808.1164 | J27: =J25*J26*12 -> 3094.8023 | K27: =K25*K26*12 -> 3392.0072 | L27: =L25*L26*12 -> 3697.204
B28: Rest of World | C28: Growth spread | D28: 0.04
B29: Closing Premium subs | C29: m | E29: 56 | F29: =E29*(1+F$6+$D$28-F$11) -> 62.171708 | G29: =F29*(1+G$6+$D$28-G$11) -> 68.660926 | H29: =G29*(1+H$6+$D$28-H$11) -> 75.426939 | I29: =H29*(1+I$6+$D$28-I$11) -> 82.4197 | J29: =I29*(1+J$6+$D$28-J$11) -> 89.579972 | K29: =J29*(1+K$6+$D$28-K$11) -> 96.839748 | L29: =K29*(1+L$6+$D$28-L$11) -> 104.12298
B30: Average subs | C30: m | F30: =AVERAGE(E29,F29) -> 59.085854 | G30: =AVERAGE(F29,G29) -> 65.416317 | H30: =AVERAGE(G29,H29) -> 72.043932 | I30: =AVERAGE(H29,I29) -> 78.923319 | J30: =AVERAGE(I29,J29) -> 85.999836 | K30: =AVERAGE(J29,K29) -> 93.20986 | L30: =AVERAGE(K29,L29) -> 100.48136
B31: Monthly ARPU | C31: € | E31: 1.95 | F31: =E31*(1+F$7) -> 2.028 | G31: =F31*(1+G$7) -> 2.10912 | H31: =G31*(1+H$7) -> 2.1934848 | I31: =H31*(1+I$7) -> 2.2812242 | J31: =I31*(1+J$7) -> 2.3724732 | K31: =J31*(1+K$7) -> 2.4673721 | L31: =K31*(1+L$7) -> 2.566067
B32: Premium revenue | C32: €m | F32: =F30*F31*12 -> 1437.9133 | G32: =G30*G31*12 -> 1655.6503 | H32: =H30*H31*12 -> 1896.3272 | I32: =I30*I31*12 -> 2160.5014 | J32: =J30*J31*12 -> 2448.3876 | K32: =K30*K31*12 -> 2759.8009 | L32: =L30*L31*12 -> 3094.1029
B34: Total closing Premium subscribers | C34: m | E34: =E14+E19+E24+E29 -> 309 | F34: =F14+F19+F24+F29 -> 330.6546 | G34: =G14+G19+G24+G29 -> 352.05168 | H34: =H14+H19+H24+H29 -> 372.94664 | I34: =I14+I19+I24+I29 -> 393.08641 | J34: =J14+J19+J24+J29 -> 412.2142 | K34: =K14+K19+K24+K29 -> 430.07468 | L34: =L14+L19+L24+L29 -> 446.4195
B35: Average Premium subscribers | C35: m | F35: =AVERAGE(E34,F34) -> 319.8273 | G35: =AVERAGE(F34,G34) -> 341.35314 | H35: =AVERAGE(G34,H34) -> 362.49916 | I35: =AVERAGE(H34,I34) -> 383.01653 | J35: =AVERAGE(I34,J34) -> 402.65031 | K35: =AVERAGE(J34,K34) -> 421.14444 | L35: =AVERAGE(K34,L34) -> 438.24709
B36: Churned subscribers (memo) | C36: m | F36: =E34*(1-(1-F8)^12) -> 68.00293 | G36: =F34*(1-(1-G8)^12) -> 72.768549 | H36: =G34*(1-(1-H8)^12) -> 77.477493 | I36: =H34*(1-(1-I8)^12) -> 82.075936 | J36: =I34*(1-(1-J8)^12) -> 86.50818 | K36: =J34*(1-(1-K8)^12) -> 90.717712 | L36: =K34*(1-(1-L8)^12) -> 94.648344
B37: Implied gross adds (memo) | C37: m | F37: =F34-E34+F36 -> 89.657532 | G37: =G34-F34+G36 -> 94.165625 | H37: =H34-G34+H36 -> 98.372458 | I37: =I34-H34+I36 -> 102.21571 | J37: =J34-I34+J36 -> 105.63596 | K37: =K34-J34+K36 -> 108.5782 | L37: =L34-K34+L36 -> 110.99317
B38: Blended monthly ARPU | C38: € | F38: =F39/F35/12 -> 5.0579557 | G38: =G39/G35/12 -> 5.2068871 | H38: =H39/H35/12 -> 5.3591001 | I38: =I39/I35/12 -> 5.5146202 | J38: =J39/J35/12 -> 5.6734732 | K38: =K39/K35/12 -> 5.8356852 | L38: =L39/L35/12 -> 6.0012829
B39: Premium revenue | C39: €m | E39: 17700 | F39: =F17+F22+F27+F32 -> 19412.068 | G39: =G17+G22+G27+G32 -> 21328.647 | H39: =H17+H22+H27+H32 -> 23312.031 | I39: =I17+I22+I27+I32 -> 25346.288 | J39: =J17+J22+J27+J32 -> 27413.109 | K39: =K17+K22+K27+K32 -> 29491.996 | L39: =L17+L22+L27+L32 -> 31560.537
B40: Premium revenue growth | C40: % | F40: =F39/E39-1 -> 0.096727005 | G40: =G39/F39-1 -> 0.098731331 | H40: =H39/G39-1 -> 0.09299155 | I40: =I39/H39-1 -> 0.087262104 | J40: =J39/I39-1 -> 0.081543321 | K40: =K39/J39-1 -> 0.075835531 | L40: =L39/K39-1 -> 0.070139063
B41: AD-SUPPORTED
B42: Ad-supported MAU growth p.a. | C42: % | D42: Input | E42: 0.06
...

Sheet 3_Financial_Statements
B1: 3 | Integrated Financial Statements (IFRS basis, simplified) | J1: Master check: | K1: ='0_Dashboard_Toggles'!$D$49 -> OK
B2: Income statement → cash flow → balance sheet; debt and interest from Tab 4 | E2: Close / LTM
B3: Fiscal year (Dec YE) | E3: 2026 | F3: 2027 | G3: 2028 | H3: 2029 | I3: 2030 | J3: 2031 | K3: 2032 | L3: 2033
B4: Period (t) | E4: 0 | F4: 1 | G4: 2 | H4: 3 | I4: 4 | J4: 5 | K4: 6 | L4: 7
B5: Revenue | C5: €m | E5: ='2_Operating_Build'!E47 -> 19550 | F5: ='2_Operating_Build'!F47 -> 21410.068 | G5: ='2_Operating_Build'!G47 -> 23486.487 | H5: ='2_Operating_Build'!H47 -> 25642.498 | I5: ='2_Operating_Build'!I47 -> 27863.193 | J5: ='2_Operating_Build'!J47 -> 30131.366 | K5: ='2_Operating_Build'!K47 -> 32427.714 | L5: ='2_Operating_Build'!L47 -> 34731.112
B6: Cost of revenue | C6: €m | E6: =-'2_Operating_Build'!E59 -> -13098.35 | F6: =-'2_Operating_Build'!F59 -> -14149.442 | G6: =-'2_Operating_Build'!G59 -> -15307.747 | H6: =-'2_Operating_Build'!H59 -> -16481.705 | I6: =-'2_Operating_Build'!I59 -> -17659.901 | J6: =-'2_Operating_Build'!J59 -> -18829.956 | K6: =-'2_Operating_Build'!K59 -> -19978.737 | L6: =-'2_Operating_Build'!L59 -> -21092.604
B7: Gross profit | C7: €m | E7: =E5+E6 -> 6451.65 | F7: =F5+F6 -> 7260.6258 | G7: =G5+G6 -> 8178.7407 | H7: =H5+H6 -> 9160.7932 | I7: =I5+I6 -> 10203.291 | J7: =J5+J6 -> 11301.41 | K7: =K5+K6 -> 12448.977 | L7: =L5+L6 -> 13638.508
B8: Research & development | C8: €m | E8: =-'2_Operating_Build'!E66 -> -1544.45 | F8: =-'2_Operating_Build'!F66 -> -1627.1652 | G8: =-'2_Operating_Build'!G66 -> -1714.5136 | H8: =-'2_Operating_Build'!H66 -> -1794.9749 | I8: =-'2_Operating_Build'!I66 -> -1950.4235 | J8: =-'2_Operating_Build'!J66 -> -2109.1956 | K8: =-'2_Operating_Build'!K66 -> -2269.94 | L8: =-'2_Operating_Build'!L66 -> -2431.1779
B9: Sales & marketing | C9: €m | E9: =-'2_Operating_Build'!E67 -> -1544.45 | F9: =-'2_Operating_Build'!F67 -> -1627.1652 | G9: =-'2_Operating_Build'!G67 -> -1714.5136 | H9: =-'2_Operating_Build'!H67 -> -1794.9749 | I9: =-'2_Operating_Build'!I67 -> -1950.4235 | J9: =-'2_Operating_Build'!J67 -> -2109.1956 | K9: =-'2_Operating_Build'!K67 -> -2269.94 | L9: =-'2_Operating_Build'!L67 -> -2431.1779
B10: General & administrative | C10: €m | E10: =-'2_Operating_Build'!E68 -> -527.85 | F10: =-'2_Operating_Build'!F68 -> -563.79846 | G10: =-'2_Operating_Build'!G68 -> -602.81984 | H10: =-'2_Operating_Build'!H68 -> -641.06246 | I10: =-'2_Operating_Build'!I68 -> -696.57982 | J10: =-'2_Operating_Build'!J68 -> -753.28414 | K10: =-'2_Operating_Build'!K68 -> -810.69285 | L10: =-'2_Operating_Build'!L68 -> -868.27781
B11: EBIT | C11: €m | E11: =SUM(E7:E10) -> 2834.9 | F11: =SUM(F7:F10) -> 3442.497 | G11: =SUM(G7:G10) -> 4146.8937 | H11: =SUM(H7:H10) -> 4929.7809 | I11: =SUM(I7:I10) -> 5605.8647 | J11: =SUM(J7:J10) -> 6329.7344 | K11: =SUM(K7:K10) -> 7098.4043 | L11: =SUM(L7:L10) -> 7907.875
B12: Interest expense (cash) | C12: €m | F12: =-'4_Debt_Schedule'!F56 -> -1272.255 | G12: =-'4_Debt_Schedule'!G56 -> -1119.2648 | H12: =-'4_Debt_Schedule'!H56 -> -951.66878 | I12: =-'4_Debt_Schedule'!I56 -> -725.15742 | J12: =-'4_Debt_Schedule'!J56 -> -532.125 | K12: =-'4_Debt_Schedule'!K56 -> -532.125 | L12: =-'4_Debt_Schedule'!L56 -> -532.125
B13: Interest income on cash | C13: €m | F13: ='4_Debt_Schedule'!F57 -> 47.76 | G13: ='4_Debt_Schedule'!G57 -> 30 | H13: ='4_Debt_Schedule'!H57 -> 30 | I13: ='4_Debt_Schedule'!I57 -> 30 | J13: ='4_Debt_Schedule'!J57 -> 56.819112 | K13: ='4_Debt_Schedule'!K57 -> 158.77528 | L13: ='4_Debt_Schedule'!L57 -> 274.36042
B14: Amortisation of financing fees & OID | C14: €m | F14: =-'4_Debt_Schedule'!F58 -> -69.457143 | G14: =-'4_Debt_Schedule'!G58 -> -69.457143 | H14: =-'4_Debt_Schedule'!H58 -> -69.457143 | I14: =-'4_Debt_Schedule'!I58 -> -69.457143 | J14: =-'4_Debt_Schedule'!J58 -> -69.457143 | K14: =-'4_Debt_Schedule'!K58 -> -69.457143 | L14: =-'4_Debt_Schedule'!L58 -> -69.457143
B15: Profit before tax | C15: €m | F15: =F11+F12+F13+F14 -> 2148.5448 | G15: =G11+G12+G13+G14 -> 2988.1717 | H15: =H11+H12+H13+H14 -> 3938.655 | I15: =I11+I12+I13+I14 -> 4841.2501 | J15: =J11+J12+J13+J14 -> 5784.9714 | K15: =K11+K12+K13+K14 -> 6655.5974 | L15: =L11+L12+L13+L14 -> 7580.6532
B17: Net interest expense (tax basis) | C17: €m | F17: =-(F12+F13+F14) -> 1293.9521 | G17: =-(G12+G13+G14) -> 1158.7219 | H17: =-(H12+H13+H14) -> 991.12592 | I17: =-(I12+I13+I14) -> 764.61457 | J17: =-(J12+J13+J14) -> 544.76303 | K17: =-(K12+K13+K14) -> 442.80686 | L17: =-(L12+L13+L14) -> 327.22173
B18: ATAD cap: max(€3m, 30% × tax-EBITDA) | C18: €m | F18: =MAX(3,'0_Dashboard_Toggles'!$C$19*'2_Operating_Build'!F79) -> 1127.1675 | G18: =MAX(3,'0_Dashboard_Toggles'!$C$19*'2_Operating_Build'!G79) -> 1347.6435 | H18: =MAX(3,'0_Dashboard_Toggles'!$C$19*'2_Operating_Build'!H79) -> 1592.0177 | I18: =MAX(3,'0_Dashboard_Toggles'!$C$19*'2_Operating_Build'!I79) -> 1804.6361 | J18: =MAX(3,'0_Dashboard_Toggles'!$C$19*'2_Operating_Build'!J79) -> 2031.7996 | K18: =MAX(3,'0_Dashboard_Toggles'!$C$19*'2_Operating_Build'!K79) -> 2272.5275 | L18: =MAX(3,'0_Dashboard_Toggles'!$C$19*'2_Operating_Build'!L79) -> 2525.5267
B19: Disallowed interest carried forward – opening | C19: €m | F19: =E21 -> 0 | G19: =F21 -> 166.78465 | H19: =G21 -> 0 | I19: =H21 -> 0 | J19: =I21 -> 0 | K19: =J21 -> 0 | L19: =K21 -> 0
B20: Deductible interest | C20: €m | F20: =MIN(F17+F19,F18) -> 1127.1675 | G20: =MIN(G17+G19,G18) -> 1325.5066 | H20: =MIN(H17+H19,H18) -> 991.12592 | I20: =MIN(I17+I19,I18) -> 764.61457 | J20: =MIN(J17+J19,J18) -> 544.76303 | K20: =MIN(K17+K19,K18) -> 442.80686 | L20: =MIN(L17+L19,L18) -> 327.22173
B21: Disallowed interest carried forward – closing | C21: €m | E21: 0 | F21: =F19+F17-F20 -> 166.78465 | G21: =G19+G17-G20 -> 0 | H21: =H19+H17-H20 -> 0 | I21: =I19+I17-I20 -> 0 | J21: =J19+J17-J20 -> 0 | K21: =K19+K17-K20 -> 0 | L21: =L19+L17-L20 -> 0
B22: Taxable income | C22: €m | F22: =F11-F20 -> 2315.3295 | G22: =G11-G20 -> 2821.3871 | H22: =H11-H20 -> 3938.655 | I22: =I11-I20 -> 4841.2501 | J22: =J11-J20 -> 5784.9714 | K22: =K11-K20 -> 6655.5974 | L22: =L11-L20 -> 7580.6532
B23: Corporate income tax | C23: €m | F23: =-MAX(0,F22)*'0_Dashboard_Toggles'!$C$18 -> -577.44318 | G23: =-MAX(0,G22)*'0_Dashboard_Toggles'!$C$18 -> -703.65394 | H23: =-MAX(0,H22)*'0_Dashboard_Toggles'!$C$18 -> -982.30056 | I23: =-MAX(0,I22)*'0_Dashboard_Toggles'!$C$18 -> -1207.4078 | J23: =-MAX(0,J22)*'0_Dashboard_Toggles'!$C$18 -> -1442.7719 | K23: =-MAX(0,K22)*'0_Dashboard_Toggles'!$C$18 -> -1659.906 | L23: =-MAX(0,L22)*'0_Dashboard_Toggles'!$C$18 -> -1890.6149
B24: Pillar Two top-up tax (15% GloBE floor) | C24: €m | F24: =-MAX(0,0.15*F22+F23) -> 0 | G24: =-MAX(0,0.15*G22+G23) -> 0 | H24: =-MAX(0,0.15*H22+H23) -> 0 | I24: =-MAX(0,0.15*I22+I23) -> 0 | J24: =-MAX(0,0.15*J22+J23) -> 0 | K24: =-MAX(0,0.15*K22+K23) -> 0 | L24: =-MAX(0,0.15*L22+L23) -> 0
B25: Net income | C25: €m | F25: =F15+F23+F24 -> 1571.1017 | G25: =G15+G23+G24 -> 2284.5178 | H25: =H15+H23+H24 -> 2956.3545 | I25: =I15+I23+I24 -> 3633.8423 | J25: =J15+J23+J24 -> 4342.1995 | K25: =K15+K23+K24 -> 4995.6914 | L25: =L15+L23+L24 -> 5690.0383
B27: CASH FLOW STATEMENT
B28: Net income | C28: €m | F28: =F25 -> 1571.1017 | G28: =G25 -> 2284.5178 | H28: =H25 -> 2956.3545 | I28: =I25 -> 3633.8423 | J28: =J25 -> 4342.1995 | K28: =K25 -> 4995.6914 | L28: =L25 -> 5690.0383
B29: D&A | C29: €m | F29: ='2_Operating_Build'!F74 -> 139.16544 | G29: ='2_Operating_Build'!G74 -> 152.66217 | H29: ='2_Operating_Build'!H74 -> 166.67624 | I29: ='2_Operating_Build'!I74 -> 181.11075 | J29: ='2_Operating_Build'!J74 -> 195.85388 | K29: ='2_Operating_Build'!K74 -> 210.78014 | L29: ='2_Operating_Build'!L74 -> 225.75223
B30: Non-cash SBC / MIP | C30: €m | F30: ='2_Operating_Build'!F78 -> 175.56256 | G30: ='2_Operating_Build'!G78 -> 192.5892 | H30: ='2_Operating_Build'!H78 -> 210.26849 | I30: ='2_Operating_Build'!I78 -> 228.47818 | J30: ='2_Operating_Build'!J78 -> 247.0772 | K30: ='2_Operating_Build'!K78 -> 265.90725 | L30: ='2_Operating_Build'!L78 -> 284.79512
B31: Amortisation of financing fees | C31: €m | F31: =-F14 -> 69.457143 | G31: =-G14 -> 69.457143 | H31: =-H14 -> 69.457143 | I31: =-I14 -> 69.457143 | J31: =-J14 -> 69.457143 | K31: =-K14 -> 69.457143 | L31: =-L14 -> 69.457143
B32: (Increase)/decrease in net working capital | C32: €m | F32: =-('2_Operating_Build'!F85-'2_Operating_Build'!E85) -> 367.16125 | G32: =-('2_Operating_Build'!G85-'2_Operating_Build'!F85) -> 409.86712 | H32: =-('2_Operating_Build'!H85-'2_Operating_Build'!G85) -> 425.57786 | I32: =-('2_Operating_Build'!I85-'2_Operating_Build'!H85) -> 438.34574 | J32: =-('2_Operating_Build'!J85-'2_Operating_Build'!I85) -> 447.7176 | K32: =-('2_Operating_Build'!K85-'2_Operating_Build'!J85) -> 453.27917 | L32: =-('2_Operating_Build'!L85-'2_Operating_Build'!K85) -> 454.67081
B33: Cash flow from operations | C33: €m | F33: =SUM(F28:F32) -> 2322.4481 | G33: =SUM(G28:G32) -> 3109.0934 | H33: =SUM(H28:H32) -> 3828.3342 | I33: =SUM(I28:I32) -> 4551.2341 | J33: =SUM(J28:J32) -> 5302.3053 | K33: =SUM(K28:K32) -> 5995.1151 | L33: =SUM(L28:L32) -> 6724.7136
B34: Capital expenditure | C34: €m | F34: =-'2_Operating_Build'!F83 -> -96.345306 | G34: =-'2_Operating_Build'!G83 -> -105.68919 | H34: =-'2_Operating_Build'!H83 -> -115.39124 | I34: =-'2_Operating_Build'!I83 -> -125.38437 | J34: =-'2_Operating_Build'!J83 -> -135.59115 | K34: =-'2_Operating_Build'!K83 -> -145.92471 | L34: =-'2_Operating_Build'!L83 -> -156.29
B35: Lease principal payments | C35: €m | F35: =-'4_Debt_Schedule'!F52 -> -75.2 | G35: =-'4_Debt_Schedule'!G52 -> -71.732027 | H35: =-'4_Debt_Schedule'!H52 -> -69.649498 | I35: =-'4_Debt_Schedule'!I52 -> -68.762578 | J35: =-'4_Debt_Schedule'!J52 -> -68.905842 | K35: =-'4_Debt_Schedule'!K52 -> -69.933454 | L35: =-'4_Debt_Schedule'!L52 -> -71.715187
B36: Free cash flow before debt service | C36: €m | F36: =F33+F34+F35 -> 2150.9028 | G36: =G33+G34+G35 -> 2931.6722 | H36: =H33+H34+H35 -> 3643.2934 | I36: =I33+I34+I35 -> 4357.0872 | J36: =J33+J34+J35 -> 5097.8083 | K36: =K33+K34+K35 -> 5779.257 | L36: =L33+L34+L35 -> 6496.7084
B37: Recap: net debt proceeds less dividends paid (net cash effect) | F37: ='4_Debt_Schedule'!F84-'4_Debt_Schedule'!F87-'4_Debt_Schedule'!F89 -> 0 | G37: ='4_Debt_Schedule'!G84-'4_Debt_Schedule'!G87-'4_Debt_Schedule'!G89 -> 0 | H37: ='4_Debt_Schedule'!H84-'4_Debt_Schedule'!H87-'4_Debt_Schedule'!H89 -> 0 | I37: ='4_Debt_Schedule'!I84-'4_Debt_Schedule'!I87-'4_Debt_Schedule'!I89 -> 0 | J37: ='4_Debt_Schedule'!J84-'4_Debt_Schedule'!J87-'4_Debt_Schedule'!J89 -> 0 | K37: ='4_Debt_Schedule'!K84-'4_Debt_Schedule'!K87-'4_Debt_Schedule'!K89 -> 0 | L37: ='4_Debt_Schedule'!L84-'4_Debt_Schedule'!L87-'4_Debt_Schedule'!L89 -> 0
B38: TLA mandatory amortisation | C38: €m | F38: =-'4_Debt_Schedule'!F28 -> -404 | G38: =-'4_Debt_Schedule'!G28 -> -404 | H38: =-'4_Debt_Schedule'!H28 -> 0 | I38: =-'4_Debt_Schedule'!I28 -> 0 | J38: =-'4_Debt_Schedule'!J28 -> 0 | K38: =-'4_Debt_Schedule'!K28 -> 0 | L38: =-'4_Debt_Schedule'!L28 -> 0
B39: TLA optional prepayment (sweep) | C39: €m | F39: =-'4_Debt_Schedule'!F29 -> -2634.9028 | G39: =-'4_Debt_Schedule'!G29 -> -597.09724 | H39: =-'4_Debt_Schedule'!H29 -> 0 | I39: =-'4_Debt_Schedule'!I29 -> 0 | J39: =-'4_Debt_Schedule'!J29 -> 0 | K39: =-'4_Debt_Schedule'!K29 -> 0 | L39: =-'4_Debt_Schedule'!L29 -> 0
B40: TLB optional prepayment (sweep) | C40: €m | F40: =-'4_Debt_Schedule'!F35 -> 0 | G40: =-'4_Debt_Schedule'!G35 -> -1930.575 | H40: =-'4_Debt_Schedule'!H35 -> -3643.2934 | I40: =-'4_Debt_Schedule'!I35 -> -3016.1316 | J40: =-'4_Debt_Schedule'!J35 -> 0 | K40: =-'4_Debt_Schedule'!K35 -> 0 | L40: =-'4_Debt_Schedule'!L35 -> 0
B41: RCF drawdown / (repayment) | C41: €m | F41: ='4_Debt_Schedule'!F22 -> 0 | G41: ='4_Debt_Schedule'!G22 -> 0 | H41: ='4_Debt_Schedule'!H22 -> 0 | I41: ='4_Debt_Schedule'!I22 -> 0 | J41: ='4_Debt_Schedule'!J22 -> 0 | K41: ='4_Debt_Schedule'!K22 -> 0 | L41: ='4_Debt_Schedule'!L22 -> 0
B42: Net change in cash | C42: €m | F42: =F36+SUM(F38:F41)+F37 -> -888 | G42: =G36+SUM(G38:G41)+G37 -> 0 | H42: =H36+SUM(H38:H41)+H37 -> 0 | I42: =I36+SUM(I38:I41)+I37 -> 1340.9556 | J42: =J36+SUM(J38:J41)+J37 -> 5097.8083 | K42: =K36+SUM(K38:K41)+K37 -> 5779.257 | L42: =L36+SUM(L38:L41)+L37 -> 6496.7084
...

Sheet 4_Debt_Schedule
B1: 4 | Debt Schedule – Multi-Tranche European Capital Structure & Cash Sweep | J1: Master check: | K1: ='0_Dashboard_Toggles'!$D$49 -> OK
B2: Circularity: CircOn=1 uses average balances (enable iterative calc: 100 iterations, 0.001) or run macro SolveInterestCircularity | E2: Close / LTM
B3: Fiscal year (Dec YE) | E3: 2026 | F3: 2027 | G3: 2028 | H3: 2029 | I3: 2030 | J3: 2031 | K3: 2032 | L3: 2033
B4: Period (t) | E4: 0 | F4: 1 | G4: 2 | H4: 3 | I4: 4 | J4: 5 | K4: 6 | L4: 7
B5: RATES
B6: 3M EURIBOR forward curve | C6: % | D6: Input – refresh from Bloomberg EUR 3M forwards | F6: 0.021 | G6: 0.022 | H6: 0.023 | I6: 0.024 | J6: 0.025 | K6: 0.025 | L6: 0.025
B7: EURIBOR incl. scenario shift | C7: % | F7: =MAX(0,F6+'0_Dashboard_Toggles'!$H$34/10000) -> 0.021 | G7: =MAX(0,G6+'0_Dashboard_Toggles'!$H$34/10000) -> 0.022 | H7: =MAX(0,H6+'0_Dashboard_Toggles'!$H$34/10000) -> 0.023 | I7: =MAX(0,I6+'0_Dashboard_Toggles'!$H$34/10000) -> 0.024 | J7: =MAX(0,J6+'0_Dashboard_Toggles'!$H$34/10000) -> 0.025 | K7: =MAX(0,K6+'0_Dashboard_Toggles'!$H$34/10000) -> 0.025 | L7: =MAX(0,L6+'0_Dashboard_Toggles'!$H$34/10000) -> 0.025
B8: Yield on cash deposits | C8: % | D8: Input | E8: 0.02
B10: TRANCHE TERMS | C10: Size €m | D10: Margin / coupon | E10: Maturity (FY) | F10: Amort. % p.a.
B11: Term Loan A (senior secured, amortising) | C11: ='1_Transaction_Summary'!C42 -> 4040 | D11: 0.0325 | E11: 2033 | F11: 0.1
B12: Term Loan B (senior secured, bullet, 0% floor) | C12: ='1_Transaction_Summary'!C43 -> 8590 | D12: 0.04 | E12: 2034 | F12: 0
B13: Senior Unsecured Notes (fixed, NC3) | C13: ='1_Transaction_Summary'!C44 -> 7070 | D13: 0.075 | E13: 2034 | F13: 0
B14: RCF margin (drawn) | D14: 0.03 | E14: 2032
B15: RCF commitment (limit) | undrawn fee | C15: 500 | D15: 0.00375
B17: CASH AVAILABLE FOR DEBT SWEEP
B18: Opening cash | C18: €m | F18: ='3_Financial_Statements'!E44 -> 2388 | G18: ='3_Financial_Statements'!F44 -> 1500 | H18: ='3_Financial_Statements'!G44 -> 1500 | I18: ='3_Financial_Statements'!H44 -> 1500 | J18: ='3_Financial_Statements'!I44 -> 2840.9556 | K18: ='3_Financial_Statements'!J44 -> 7938.7639 | L18: ='3_Financial_Statements'!K44 -> 13718.021
B19: Free cash flow before debt service | C19: €m | F19: ='3_Financial_Statements'!F36 -> 2150.9028 | G19: ='3_Financial_Statements'!G36 -> 2931.6722 | H19: ='3_Financial_Statements'!H36 -> 3643.2934 | I19: ='3_Financial_Statements'!I36 -> 4357.0872 | J19: ='3_Financial_Statements'!J36 -> 5097.8083 | K19: ='3_Financial_Statements'!K36 -> 5779.257 | L19: ='3_Financial_Statements'!L36 -> 6496.7084
B20: Less: TLA mandatory amortisation | C20: €m | F20: =-F28 -> -404 | G20: =-G28 -> -404 | H20: =-H28 -> 0 | I20: =-I28 -> 0 | J20: =-J28 -> 0 | K20: =-K28 -> 0 | L20: =-L28 -> 0
B21: Cash available after mandatory debt service and minimum cash | C21: €m | F21: =F18+F19+F20-'0_Dashboard_Toggles'!$C$13 -> 2634.9028 | G21: =G18+G19+G20-'0_Dashboard_Toggles'!$C$13 -> 2527.6722 | H21: =H18+H19+H20-'0_Dashboard_Toggles'!$C$13 -> 3643.2934 | I21: =I18+I19+I20-'0_Dashboard_Toggles'!$C$13 -> 4357.0872 | J21: =J18+J19+J20-'0_Dashboard_Toggles'!$C$13 -> 6438.7639 | K21: =K18+K19+K20-'0_Dashboard_Toggles'!$C$13 -> 12218.021 | L21: =L18+L19+L20-'0_Dashboard_Toggles'!$C$13 -> 18714.729
B22: RCF drawdown / (repayment) | C22: €m | F22: =IF(F21<0,MIN(-F21,$C$15-E47),-MIN(E47,F21)) -> 0 | G22: =IF(G21<0,MIN(-G21,$C$15-F47),-MIN(F47,G21)) -> 0 | H22: =IF(H21<0,MIN(-H21,$C$15-G47),-MIN(G47,H21)) -> 0 | I22: =IF(I21<0,MIN(-I21,$C$15-H47),-MIN(H47,I21)) -> 0 | J22: =IF(J21<0,MIN(-J21,$C$15-I47),-MIN(I47,J21)) -> 0 | K22: =IF(K21<0,MIN(-K21,$C$15-J47),-MIN(J47,K21)) -> 0 | L22: =IF(L21<0,MIN(-L21,$C$15-K47),-MIN(K47,L21)) -> 0
B23: Cash available for optional sweep | C23: €m | F23: =MAX(0,F21+MIN(0,F22)) -> 2634.9028 | G23: =MAX(0,G21+MIN(0,G22)) -> 2527.6722 | H23: =MAX(0,H21+MIN(0,H22)) -> 3643.2934 | I23: =MAX(0,I21+MIN(0,I22)) -> 4357.0872 | J23: =MAX(0,J21+MIN(0,J22)) -> 6438.7639 | K23: =MAX(0,K21+MIN(0,K22)) -> 12218.021 | L23: =MAX(0,L21+MIN(0,L22)) -> 18714.729
B24: Cash applied to sweep | C24: €m | F24: =F23*'0_Dashboard_Toggles'!$C$11*'0_Dashboard_Toggles'!$C$12 -> 2634.9028 | G24: =G23*'0_Dashboard_Toggles'!$C$11*'0_Dashboard_Toggles'!$C$12 -> 2527.6722 | H24: =H23*'0_Dashboard_Toggles'!$C$11*'0_Dashboard_Toggles'!$C$12 -> 3643.2934 | I24: =I23*'0_Dashboard_Toggles'!$C$11*'0_Dashboard_Toggles'!$C$12 -> 4357.0872 | J24: =J23*'0_Dashboard_Toggles'!$C$11*'0_Dashboard_Toggles'!$C$12 -> 6438.7639 | K24: =K23*'0_Dashboard_Toggles'!$C$11*'0_Dashboard_Toggles'!$C$12 -> 12218.021 | L24: =L23*'0_Dashboard_Toggles'!$C$11*'0_Dashboard_Toggles'!$C$12 -> 18714.729
B26: TERM LOAN A (E + 325 bps, 7-yr, 10% p.a. amortisation, balloon FY33)
B27: Opening balance | C27: €m | F27: =E31 -> 4040 | G27: =F31 -> 1001.0972 | H27: =G31 -> 0 | I27: =H31 -> 0 | J27: =I31 -> 0 | K27: =J31 -> 0 | L27: =K31 -> 0
B28: Mandatory amortisation | C28: €m | F28: =IF(F$3>=$E$11,F27,MIN(F27,$C$11*$F$11)) -> 404 | G28: =IF(G$3>=$E$11,G27,MIN(G27,$C$11*$F$11)) -> 404 | H28: =IF(H$3>=$E$11,H27,MIN(H27,$C$11*$F$11)) -> 0 | I28: =IF(I$3>=$E$11,I27,MIN(I27,$C$11*$F$11)) -> 0 | J28: =IF(J$3>=$E$11,J27,MIN(J27,$C$11*$F$11)) -> 0 | K28: =IF(K$3>=$E$11,K27,MIN(K27,$C$11*$F$11)) -> 0 | L28: =IF(L$3>=$E$11,L27,MIN(L27,$C$11*$F$11)) -> 0
B29: Optional prepayment (sweep) | C29: €m | F29: =MIN(F27-F28,F24) -> 2634.9028 | G29: =MIN(G27-G28,G24) -> 597.09724 | H29: =MIN(H27-H28,H24) -> 0 | I29: =MIN(I27-I28,I24) -> 0 | J29: =MIN(J27-J28,J24) -> 0 | K29: =MIN(K27-K28,K24) -> 0 | L29: =MIN(L27-L28,L24) -> 0
B30: Interest expense | C30: €m | F30: =IF('0_Dashboard_Toggles'!$C$10=1,AVERAGE(F27,F31),F27)*(F$7+$D$11) -> 216.14 | G30: =IF('0_Dashboard_Toggles'!$C$10=1,AVERAGE(G27,G31),G27)*(G$7+$D$11) -> 54.5598 | H30: =IF('0_Dashboard_Toggles'!$C$10=1,AVERAGE(H27,H31),H27)*(H$7+$D$11) -> 0 | I30: =IF('0_Dashboard_Toggles'!$C$10=1,AVERAGE(I27,I31),I27)*(I$7+$D$11) -> 0 | J30: =IF('0_Dashboard_Toggles'!$C$10=1,AVERAGE(J27,J31),J27)*(J$7+$D$11) -> 0 | K30: =IF('0_Dashboard_Toggles'!$C$10=1,AVERAGE(K27,K31),K27)*(K$7+$D$11) -> 0 | L30: =IF('0_Dashboard_Toggles'!$C$10=1,AVERAGE(L27,L31),L27)*(L$7+$D$11) -> 0
B31: Closing balance | C31: €m | E31: =C11 -> 4040 | F31: =F27-F28-F29 -> 1001.0972 | G31: =G27-G28-G29 -> 0 | H31: =H27-H28-H29 -> 0 | I31: =I27-I28-I29 -> 0 | J31: =J27-J28-J29 -> 0 | K31: =K27-K28-K29 -> 0 | L31: =L27-L28-L29 -> 0
B33: TERM LOAN B (E + 400 bps, 8-yr bullet, swept after TLA)
B34: Opening balance | C34: €m | F34: =E36 -> 8590 | G34: =F36 -> 8590 | H34: =G36 -> 6659.425 | I34: =H36 -> 3016.1316 | J34: =I36 -> 0 | K34: =J36 -> 0 | L34: =K36 -> 0
B35: Optional prepayment (sweep) | C35: €m | F35: =MIN(F34,F24-F29) -> 0 | G35: =MIN(G34,G24-G29) -> 1930.575 | H35: =MIN(H34,H24-H29) -> 3643.2934 | I35: =MIN(I34,I24-I29) -> 3016.1316 | J35: =MIN(J34,J24-J29) -> 0 | K35: =MIN(K34,K24-K29) -> 0 | L35: =MIN(L34,L24-L29) -> 0
B36: Closing balance | C36: €m | E36: =C12 -> 8590 | F36: =F34-F35 -> 8590 | G36: =G34-G35 -> 6659.425 | H36: =H34-H35 -> 3016.1316 | I36: =I34-I35 -> 0 | J36: =J34-J35 -> 0 | K36: =K34-K35 -> 0 | L36: =L34-L35 -> 0
B37: Interest expense | C37: €m | F37: =IF('0_Dashboard_Toggles'!$C$10=1,AVERAGE(F34,F36),F34)*(F$7+$D$12) -> 523.99 | G37: =IF('0_Dashboard_Toggles'!$C$10=1,AVERAGE(G34,G36),G34)*(G$7+$D$12) -> 532.58 | H37: =IF('0_Dashboard_Toggles'!$C$10=1,AVERAGE(H34,H36),H34)*(H$7+$D$12) -> 419.54378 | I37: =IF('0_Dashboard_Toggles'!$C$10=1,AVERAGE(I34,I36),I34)*(I$7+$D$12) -> 193.03242 | J37: =IF('0_Dashboard_Toggles'!$C$10=1,AVERAGE(J34,J36),J34)*(J$7+$D$12) -> 0 | K37: =IF('0_Dashboard_Toggles'!$C$10=1,AVERAGE(K34,K36),K34)*(K$7+$D$12) -> 0 | L37: =IF('0_Dashboard_Toggles'!$C$10=1,AVERAGE(L34,L36),L34)*(L$7+$D$12) -> 0
B39: SENIOR UNSECURED NOTES (7.50% fixed, 8-yr, non-call 3)
B40: Opening balance | C40: €m | F40: =E41 -> 7070 | G40: =F41 -> 7070 | H40: =G41 -> 7070 | I40: =H41 -> 7070 | J40: =I41 -> 7070 | K40: =J41 -> 7070 | L40: =K41 -> 7070
B41: Closing balance | C41: €m | E41: =C13 -> 7070 | F41: =F40 -> 7070 | G41: =G40 -> 7070 | H41: =H40 -> 7070 | I41: =I40 -> 7070 | J41: =J40 -> 7070 | K41: =K40 -> 7070 | L41: =L40 -> 7070
B42: Interest expense (fixed – no circularity) | C42: €m | F42: =F40*$D$13 -> 530.25 | G42: =G40*$D$13 -> 530.25 | H42: =H40*$D$13 -> 530.25 | I42: =I40*$D$13 -> 530.25 | J42: =J40*$D$13 -> 530.25 | K42: =K40*$D$13 -> 530.25 | L42: =L40*$D$13 -> 530.25
B44: REVOLVING CREDIT FACILITY (€500m, E + 300 bps, 37.5 bps undrawn)
B45: Opening balance | C45: €m | F45: =E47 -> 0 | G45: =F47 -> 0 | H45: =G47 -> 0 | I45: =H47 -> 0 | J45: =I47 -> 0 | K45: =J47 -> 0 | L45: =K47 -> 0
B46: Drawdown / (repayment) | C46: €m | F46: =F22 -> 0 | G46: =G22 -> 0 | H46: =H22 -> 0 | I46: =I22 -> 0 | J46: =J22 -> 0 | K46: =K22 -> 0 | L46: =L22 -> 0
...

Sheet 5_Returns_Sensitivities
B1: 5 | Returns Analysis & Sensitivities | J1: Master check: | K1: ='0_Dashboard_Toggles'!$D$49 -> OK
B2: Exit at FY2033E (7-year hold). Gross = all equity after MIP; Net = LP view on sponsor cash only after 1.5% annual fee on invested capital and 20% carry over 8% pref (full catch-up). Fees are paid annually (rows 33); carry is crystallised at exit. Interim recap dividends (if switched on) flow through rows 20/33.
B4: EXIT VALUATION BRIDGE
B5: Exit Adj. EBITDA (FY33E) | C5: ='2_Operating_Build'!L79 -> 8418.4223
B6: Exit EV / EBITDA multiple | C6: ='0_Dashboard_Toggles'!C22 -> 22
B7: Exit enterprise value | C7: =C5*C6 -> 185205.29
B8: FY33E free cash flow before debt service | C8: ='3_Financial_Statements'!L36 -> 6496.7084
B9: Implied exit EV / FCF (cross-check) | C9: =C7/C8 -> 28.507558
B10: Less: total debt | C10: =-'4_Debt_Schedule'!L61 -> -7070
B11: Plus: cash and long-term investments (non-operating, netted out of EV at entry) | C11: ='3_Financial_Statements'!L44+'3_Financial_Statements'!L50 -> 21332.729
B12: Less: lease liabilities | C12: =-'4_Debt_Schedule'!L53 -> -463.33251
B13: Exit equity value (pre-MIP) | C13: =SUM(C7,C10:C12) -> 199004.69
B14: Total equity invested (sponsor + rollover) | C14: ='1_Transaction_Summary'!C49+'1_Transaction_Summary'!C50 -> 91000.964
B15: Less: Management Incentive Plan | C15: =-'0_Dashboard_Toggles'!C20*MAX(0,C13+C21-C14) -> -8640.2979
B16: Equity proceeds to sponsor & rollover | C16: =C13+C15 -> 190364.39
B17: Gross MoIC | C17: =(C16+C21)/C14 -> 2.0918942
B18: Sponsor-only proceeds / invested (pro rata) | C18: =(C16+C21)*'1_Transaction_Summary'!C50/C14 -> 124371.29 | D18: ='1_Transaction_Summary'!C50 -> 59453.909
B19: Gross IRR | C19: =IRR(E20:L20) -> 0.11119784 | E19: 2026 | F19: 2027 | G19: 2028 | H19: 2029 | I19: 2030 | J19: 2031 | K19: 2032 | L19: 2033
D20: Equity CF | E20: =-$C$14 -> -91000.964 | F20: ='4_Debt_Schedule'!F89 -> 0 | G20: ='4_Debt_Schedule'!G89 -> 0 | H20: ='4_Debt_Schedule'!H89 -> 0 | I20: ='4_Debt_Schedule'!I89 -> 0 | J20: ='4_Debt_Schedule'!J89 -> 0 | K20: ='4_Debt_Schedule'!K89 -> 0 | L20: =$C$16+'4_Debt_Schedule'!L89 -> 190364.39
B21: Memo: cumulative interim dividends to equity (recap module) | C21: =SUM('4_Debt_Schedule'!F89:L89) -> 0
B22: NET RETURNS (LP VIEW – sponsor cash only; rollover equity pays no fee or carry; fee paid annually)
B23: Management fee (p.a. on invested) | C23: 0.015
B24: Carried interest | C24: 0.2
B25: Preferred return (hurdle) | C25: 0.08
B26: Hold period (years) | C26: ='2_Operating_Build'!L3-'2_Operating_Build'!E3 -> 7
B27: Management fees over hold (1.5% p.a. × sponsor cash) | C27: =-C23*D18*C26 -> -6242.6604
B28: Sponsor profit after fees | C28: =C18+C27-D18 -> 58674.718
B29: Preferred return amount (on sponsor cash) | C29: =D18*((1+C25)^C26-1) -> 42439.643
B30: Carry (full catch-up) | C30: =-MAX(0,MIN(C24*C28,C28-C29)) -> -11734.944
B31: Net MoIC | C31: =(C18+C27+C30)/D18 -> 1.7895154
B32: Net IRR | C32: =IF(C31>0,IRR(E33:L33),-1) -> 0.084022948
D33: Net LP cash flows | E33: =-$D$18 -> -59453.909 | F33: =F20*$D$18/$C$14-$C$23*$D$18 -> -891.80863 | G33: =G20*$D$18/$C$14-$C$23*$D$18 -> -891.80863 | H33: =H20*$D$18/$C$14-$C$23*$D$18 -> -891.80863 | I33: =I20*$D$18/$C$14-$C$23*$D$18 -> -891.80863 | J33: =J20*$D$18/$C$14-$C$23*$D$18 -> -891.80863 | K33: =K20*$D$18/$C$14-$C$23*$D$18 -> -891.80863 | L33: =L20*$D$18/$C$14-$C$23*$D$18+$C$30 -> 111744.53
B34: VALUE CREATION ATTRIBUTION
B35: Entry Adj. EBITDA (FY26E) | C35: ='2_Operating_Build'!E79 -> 3282.595
B36: Entry EV / EBITDA | C36: ='1_Transaction_Summary'!C28 -> 32.536742
B37: EBITDA growth × entry multiple | C37: =(C5-C35)*C36 -> 167103.09
B38: Multiple expansion / (compression) | C38: =(C6-C36)*C5 -> -88702.745
B39: Deleveraging & cash build (net debt incl. LT investments) | C39: =('1_Transaction_Summary'!C47-'1_Transaction_Summary'!F48-'3_Financial_Statements'!E50+'1_Transaction_Summary'!C23)-(-C10-C11-C12) -> 30463.397
B40: Fees & other leakage (plug = advisory + financing fees + OID) | C40: =C41-C37-C38-C39 -> -860.01731
B41: Total value created (exit equity − invested) | C41: =C13+C21-C14 -> 108003.72
...

Sheet 6_IC_Analysis
B1: 6 | IC Analysis – what must be true, leverage, dividend recap, size, ownership, minority alternative
B2: Sections A–C and E–G are STATIC outputs of full workbook re-runs or sourced facts (grey fill). Section D is LIVE. € millions unless stated. Run date 06-Oct-2026 (v3).
B4: A. WHAT HAS TO BE TRUE FOR A 20% GROSS IRR (one lever at a time, everything else = Base; 7-year hold)
B5: Lever | C5: Base value | D5: Needed for 20% | E5: Gross IRR | F5: Gross MoIC | G5: Net IRR | H5: Total equity €bn | I5: Sponsor equity €bn | J5: Realistic?
B6: Offer premium to unaffected ($490.30) | C6: 0.3 | D6: -0.12633792 | E6: 0.2 | F6: 3.5831808 | G6: 0.16505916 | H6: 52.262308 | I6: 31.138209 | J6: No – offer would be $428, 13% below market
B7: Exit EV / EBITDA (entry 32.5x) | C7: 22 | D7: 39.522198 | E7: 0.2 | F7: 3.5831808 | G7: 0.16505916 | H7: 91.000964 | I7: 59.453909 | J7: No – 21% ABOVE entry multiple
B8: FY33E gross margin (royalty step-down bps p.a.) | C8: 0.3926885 | D8: 0.56459263 | E8: 0.2 | F8: 3.5831808 | G8: 0.16505916 | H8: 91.000964 | I8: 59.453909 | J8: No – 340 bps p.a. vs 70; GM today 33.4%
B9: Entry leverage (x FY26E EBITDA) | C9: 6 | D9: none (15x shown) | E9: 0.13206689 | F9: 2.3828935 | G9: 0.10280552 | H9: 62.229014 | I9: 30.681959 | J9: No – 15x gives only 13.2% and covenant fails from 10x
B10: Hold period at 22x exit | C10: 7 | D10: none | E10: 0.11119784 | F10: 2.0918942 | J10: No – best case 11.1% (FY33); shorter holds are worse
B11: Hold period if exit multiple = entry 32.5x (no de-rating) | C11: 7 | D11: FY2029 (3 yrs) | E11: 0.20364032 | F11: 1.7437739 | J11: No – needs zero de-rating and a 3-year flip
B12: Structure: dividend recap / excess-cash payout (best tested) | C12: none | D12: recap FY30 to 6.0x | E12: 0.11716658 | F12: 2.0291365 | G12: 0.088636084 | H12: 91.000964 | I12: 59.453909 | J12: No – adds ≤0.6pp; debt at exit €36bn
B13: Operating case: Upside (GM 42.1%, ARPU 5%, 25x exit) | C13: Base | D13: Upside @25x | E13: 0.17656582 | F13: 3.1211425 | G13: 0.14341737 | H13: 91.000964 | I13: 59.453909 | J13: No – 17.7% even if everything goes right
B14: Upside operating case: exit multiple needed | C14: 22.0x | D14: 29.104041 | E14: 0.2 | F14: 3.5831808 | G14: 0.16505916 | H14: 91.000964 | I14: 59.453909 | J14: No – 29.1x vs 25x upside assumption
B15: Memo's own 'what you have to believe' bundle (GM 44%, 25x, ARPU 5%, zero churn penalty) | C15: 20% claimed | D15: reaches 17.4% | E15: 0.17384099 | F15: 3.0708945 | G15: 0.14091135 | H15: 91.000964 | I15: 59.453909 | J15: No – memo text (§8) overstates: bundle does NOT reach 20%
B16: Everything at once: Upside + 25x + 8x leverage + recap FY30 to 6x | C16: — | D16: — | E16: 0.1951113 | F16: 3.1839624 | G16: 0.16049811 | H16: 84.563864 | I16: 53.016809 | J16: No – 19.5%; same structure on Downside loses money (see D below)
B17: Same structure, Downside operating case at 8x leverage (no recap) | E17: -0.012958179 | F17: 0.91274378 | G17: -0.02857503 | J17: Peak net leverage 6.7x vs 7.0x covenant
B18: For reference: buy at zero premium (offer = $490.30) | C18: 0 | D18: — | E18: 0.16730265 | F18: 2.9531418 | G18: 0.13490751 | H18: 63.722685 | I18: 39.515077 | J18: Not a control deal – no seller accepts
B19: Conclusion: no single lever, and no realistic combination, reaches 20% at a 30% premium. Only the entry price does it, and that price is below the market.
B21: B. IDLE-CASH / LEVERAGE TEST – entry leverage 4x–15x (full re-runs, Base operating case, 22x exit)
B22: Entry leverage (x FY26E EBITDA) | C22: Total debt €bn | D22: Total equity €bn | E22: Sponsor equity €bn | F22: Gross IRR | G22: Gross MoIC | H22: Net IRR | I22: FY27E interest cover | J22: FY27E net leverage | K22: FY27E ATAD disallowed €m | L22: 7.0x covenant breaches | M22: Master check
B23: 4 | C23: 13.1 | D23: 97.438064 | E23: 65.891009 | F23: 0.1071987 | G23: 2.0292034 | H23: 0.082284533 | I23: 4.4380168 | J23: 2.1840077 | K23: 0 | L23: 0 | M23: OK
B24: 5 | C24: 16.4 | D24: 94.219514 | E24: 62.672459 | F24: 0.10916785 | G24: 2.0543727 | H24: 0.084065558 | I24: 3.5461075 | J24: 3.1040823 | K24: 0 | L24: 0 | M24: OK
B25: 6 | C25: 19.7 | D25: 91.000964 | E25: 59.453909 | F25: 0.11119784 | G25: 2.0805915 | H25: 0.085902358 | I25: 2.9532012 | J25: 4.0351848 | K25: 166.78465 | L25: 0 | M25: OK
B26: 7 | C26: 23 | D26: 87.782414 | E26: 56.235359 | F26: 0.11330578 | G26: 2.1081138 | H26: 0.087810642 | I26: 2.5301604 | J26: 4.9701089 | K26: 391.14036 | L26: 0 | M26: OK
B27: 8 | C27: 26.3 | D27: 84.563864 | E27: 53.016809 | F27: 0.11550031 | G27: 2.1370915 | H27: 0.089798358 | I27: 2.2128529 | J27: 5.9050901 | K27: 615.71107 | L27: 0 | M27: OK
B28: 9 | C28: 29.5 | D28: 81.442814 | E28: 49.895759 | F28: 0.11768788 | G28: 2.1663034 | H28: 0.091780358 | I28: 1.973063 | J28: 6.8117034 | K28: 833.33965 | L28: 0 | M28: OK
B29: 10 | C29: 32.8 | D29: 78.224264 | E29: 46.677209 | F29: 0.12005458 | G29: 2.1982868 | H29: 0.093925936 | I29: 1.774624 | J29: 7.7466847 | K29: 1057.9104 | L29: 1 | M29: ERROR
B30: 12 | C30: 39.4 | D30: 71.787164 | E30: 40.240109 | F30: 0.12438555 | G30: 2.257664 | H30: 0.097843494 | I30: 1.4776895 | J30: 9.6165328 | K30: 1506.6218 | L30: 2 | M30: ERROR
B31: 15 | C31: 49.2 | D31: 62.229014 | E31: 30.681959 | F31: 0.13206689 | G31: 2.3663649 | H31: 0.10480514 | I31: 1.1835121 | J31: 12.393051 | K31: 2173.1768 | L31: 3 | M31: ERROR
B32: Read-across: leverage is a weak lever. +1 turn ≈ +0.2pp gross IRR but −0.4x interest cover. FY27E ATAD cap (30% of tax-EBITDA = €1,127m) already bites at 6x (€167m disallowed, carried forward) and bites harder above it. Covenant (TLA springing 7.0x net) breaks at 10x. RCF is untouched up to 12x because the cash sweep absorbs FCF.
B34: C. DIVIDEND RECAP / EXCESS-CASH PAYOUT TEST (module in 4_Debt_Schedule rows 72–93; 6.0x entry leverage; Base case; 22x exit)
B35: Case | C35: Gross IRR | D35: Gross MoIC | E35: Net IRR | F35: Dividends paid €bn | G35: Debt at exit €bn | H35: Min interest cover after recap | I35: Peak net leverage after recap | J35: Max net interest ÷ ATAD cap | K35: Max ATAD carry-fwd €m | L35: Δ gross IRR vs none (pp) | M35: Master check
B36: No recap (base) | C36: 0.11119784 | D36: 2.0918942 | E36: 0.084022948 | F36: 0 | G36: 7.07 | H36: 2.9532012 | I36: 4.0351848 | J36: 1.1479679 | K36: 166.78465 | L36: 0 | M36: OK
B37: Pay out excess cash from FY30 (no new debt) | C37: 0.11292809 | D37: 2.0888592 | E37: 0.085458024 | F37: 18.414523 | G37: 7.07 | H37: 8.2953762 | I37: 0.92594846 | J37: 0.4236946 | K37: 0 | L37: 0.1722454 | M37: OK
B38: Pay out excess cash from FY31 (no new debt) | C38: 0.11279007 | D38: 2.0890627 | E38: 0.085347996 | F38: 18.434654 | G38: 7.07 | H38: 12.727584 | I38: 0.82242361 | J38: 0.26811848 | K38: 0 | L38: 0.15852066 | M38: OK
B39: Recap FY29 to 5.0x + excess cash | C39: 0.11664638 | D39: 2.0476748 | E39: 0.088220708 | F39: 30.788304 | G39: 23.517497 | H39: 3.0711151 | I39: 4.7173398 | J39: 1.1072464 | K39: 193.54074 | L39: 0.53955495 | M39: OK
B40: Recap FY30 to 3.0x + excess cash | C40: 0.11458131 | D40: 2.0676215 | E40: 0.086708878 | F40: 27.290173 | G40: 18.046361 | H40: 4.9969788 | I40: 2.7506422 | J40: 0.68648954 | K40: 0 | L40: 0.33552597 | M40: OK
B41: Recap FY30 to 4.0x + excess cash | C41: 0.11552723 | D41: 2.0559824 | E41: 0.087428289 | F41: 32.154359 | G41: 24.061814 | H41: 3.7490307 | I41: 3.7506422 | J41: 0.90853851 | K41: 0 | L41: 0.42897327 | M41: OK
B42: Recap FY30 to 5.0x + excess cash | C42: 0.11647537 | D42: 2.0441882 | E42: 0.088149148 | F42: 37.0032 | G42: 30.077268 | H42: 2.9998473 | I42: 4.7506422 | J42: 1.1305875 | K42: 289.92735 | L42: 0.52262322 | M42: OK
B43: Recap FY30 to 6.0x + excess cash | C43: 0.11716658 | D43: 2.0291365 | E43: 0.088636084 | F43: 41.529829 | G43: 36.092722 | H43: 2.5002188 | I43: 5.7506422 | J43: 1.3526365 | K43: 1415.005 | L43: 0.59042484 | M43: OK
...

Sheet 7_Assumptions_Register
B1: 7 | Assumptions Register – what the model assumes, where, on what basis, and how much it matters
B2: Basis tags: FILE = figure in the 6-K / 20-F as quoted in the memo; ESTIMATE = deal-team estimate pending 20-F notes; ASSUMPTION = judgement with no evidence in the file. Sensitivities = gross IRR from full model re-runs (06-Oct-2026), one input changed, rest Base (11.1%).
B4: # | C4: Assumption | D4: Model value | E4: Cell(s) | F4: Basis | G4: Evidence in the file / what it implies | H4: Sensitivity (gross IRR, full re-run) | I4: What would change my view / diligence
B5: 1 | C5: Music royalty step-down | D5: 70 bps p.a. (Base) / 110 (Up) / 15 (Down): 57.8% → 52.9% of Premium revenue FY26E→FY33E | E5: Dashboard E29:G29 → 2_Operating_Build row 50 | F5: ASSUMPTION | G5: The memo says it does NOT underwrite a lower headline rate; the step-down is meant to stand in for marketplace netting, superfan add-ons, bundling. None of these is modelled separately and no contract term in the file supports 490 bps cumulative. Q2'26 Premium GM 34.9% (+174 bps Y/Y) is the only observed datapoint. | H5: 0 bps: 7.9% | 15: 8.7% | 40: 9.8% | 70: 11.1% | 110: 12.7%. ≈0.46pp of IRR per 10 bps p.a.; 20% needs 340 bps p.a. (GM 56.5%). | I5: Label contract terms and renewal calendar; MFN clauses; split of GM gain between mix, marketplace and rate (data room, Phase 2).
B6: 2 | C6: Premium ARPU growth | D6: 4.0% p.a. (Base) / 5.0% / 2.5%; blended ARPU €5.06 → €6.00 (≈2.9% CAGR FY27–33 after regional mix) | E6: Dashboard E26:G26; regional spreads 2_Operating_Build D13/D18/D23/D28 | F6: ASSUMPTION | G6: Haircut to the observed +7% Y/Y (Q2'26, per memo). Price-neutral level assumed at 3% (2_Operating_Build E10). Regional mix (Rest of World subs growing 4pp faster) pulls blended growth below the 4% price assumption. | H6: 3%: 10.5% | 4%: 11.1% | 5%: 11.7%. ≈0.6pp per 1pp of ARPU growth (matches memo). | I6: Price-increase vintage cohorts: retention after each hike by region.
B7: 3 | C7: Churn elasticity | D7: 0.05pp extra monthly churn per 1pp of ARPU growth above 3% neutral; base monthly churn 2.0% (1.8% Up / 2.4% Down) | E7: 2_Operating_Build E9, E10, rows 8 and 11; Dashboard E27:G27 | F7: ASSUMPTION | G7: Spotify does not disclose churn; nothing in the file evidences 2.0%. DEFECT FOUND: only the ELASTICITY term drives returns (extra annual churn = (1−(1−c_elastic)^12) − (1−(1−c_base)^12), 0.5pp/yr in Base). The BASE churn level has almost no effect (1%: 11.07%, 2%: 11.12%, 3%: 11.17% – higher churn slightly HELPS), so the Downside's 2.4% churn does not hurt the downside case. | H7: Elasticity 0: 11.6% | 0.05: 11.1% | 0.10: 10.7%. Base churn 1%/2%/3%: 11.1% / 11.1% / 11.2%. | I7: Replace with a cohort-based churn build; until then do not cite the churn assumption as a downside driver.
B8: 4 | C8: SBC → cash compensation | D8: 50% of SBC becomes cash pay post-close (40% Up / 60% Down); not added back to Adj. EBITDA | E8: Dashboard E36:G36 → 2_Operating_Build rows 76–79 | F8: ASSUMPTION | G8: FY26E SBC €321m (1.6% of revenue). FY26E Adj. EBITDA (€3,283m) adds back 100% of SBC (E77 = 0%) while FY27E+ adds back only the non-cash half. Entry multiple is therefore flattered: on the post-close definition FY26E EBITDA ≈ €3,122m and EV/EBITDA ≈ 34.2x, not 32.5x. | H8: 0%: 11.7% | 50%: 11.1% | 100%: 10.5%. ≈0.6pp per 50pts. | I8: MIP terms and retention economics; which SBC is genuinely cash-substituted.
B9: 5 | C9: Negative working capital | D9: −19.7% of revenue held constant (−€3,859m at close → −€6,856m FY33E); releases €367m (FY27E) rising to €455m (FY33E) of cash p.a. | E9: 2_Operating_Build E84 (=E85/E47), F84:L84; 3_Financial_Statements row 32 | F9: FILE level (6-K balances per memo) + ASSUMPTION (constant ratio) | G9: Level is built from receivables less payables, accrued royalties and deferred revenue. Holding the ratio flat means growth keeps releasing cash. It is a liquidity risk as much as a return driver: if the ratio normalised, FY27E would swing by ≈ −€1.0bn (at −15%) or −€2.1bn (at −10%) against €1.5bn minimum cash. | H9: −15%: 11.0% | −10%: 10.8% (small on IRR; large on liquidity). | I9: Monthly liquidity model; royalty payment timing; deferred-revenue seasonality (Phase 2).
B10: 6 | C10: FX (EUR per USD) | D10: 0.8756 EUR per USD (6-K guidance rate, 30-Jun-26) | E10: Dashboard C9 → 1_Transaction_Summary C7:C8 | F10: FILE (rate) / MODEL LIMITATION (use) | G10: DEFECT/LIMITATION: FX enters ONLY by converting the $637.39 offer into euros. All revenue and costs are built in EUR; there is no USD revenue translation, no USD debt tranche and no hedge P&L, so the memo's §7 hedging programme (35% USD TLB, swaps, caps, layered cash-flow hedges) is narrative only and is not in the numbers. North America ≈ 44% of FY27E Premium revenue (€8.5bn of €19.4bn). | H10: 0.80: 12.9% | 0.8756: 11.1% | 0.95: 9.5% (entry-price effect only). | I10: Currency split of revenue, costs and LP base; build USD cash flows before relying on any hedging claim.
B11: 7 | C11: Exit multiple: 22x vs 32.5x entry | D11: 22.0x Base / 25.0x Up / 16.0x Down FY33E Adj. EBITDA; Dashboard C21 overrides | E11: Dashboard E35:G35, C21; 5_Returns_Sensitivities C6 | F11: ASSUMPTION (not derived from comps or DCF in the file) | G11: Of the 10.5-turn gap, 8.2 turns is the 30% premium itself (32.5x entry vs 24.3x unaffected, 1_Transaction_Summary C28 vs C31) and only 2.3 turns is an assumed de-rating from today's market multiple. Cross-check: implied exit EV/FCF 28.5x (5_Returns C9) vs entry EV/LTM FCF 32.8x. Nothing in the file shows why a business growing revenue 7% and EBITDA 11% in FY33E should trade at 22x rather than 18x or 25x. | H11: 16x: 6.8% | 18x: 8.3% | 22x: 11.1% | 25x: 13.0% | 32.5x: 16.9%. 20% needs 39.5x. | I11: Public comps for scaled platforms with 7–8% growth and 24% EBITDA margins; exit-route evidence (re-IPO float, continuation vehicle).
B12: 8 | C12: Ad-Supported revenue growth and margin | D12: 8% p.a. (12% Up / 3% Down); Ad GM 17.7% → 30% FY33E | E12: Dashboard E28:G28, E30:G30; 2_Operating_Build E42 (dead input) | F12: ASSUMPTION | G12: Q2'26 Ad-Supported revenue grew 1% Y/Y (memo). DEFECT FOUND: 2_Operating_Build E42 (ad MAU growth) does not drive revenue – ad revenue is the Dashboard growth rate applied to the prior year; the input only feeds a memo MAU line. | H12: 1%: 10.8% | 3%: 10.9% | 8%: 11.1% | 12%: 11.4%. | I12: Ad-tier pricing and load data.
B13: 9 | C13: Premium subscriber growth | D13: 7.5% FY27E fading linearly to 4.0% FY33E (9.0%→5.0% Up; 5.0%→3.0% Down) | E13: Dashboard E24:G25 → 2_Operating_Build row 6 | F13: ASSUMPTION | G13: Q2'26 Premium subscribers +9% Y/Y (memo). Subscribers 309m (FY26E) → 446m (FY33E). | H13: FY33E fade to 3%: 10.7% | FY27E 5%: 9.8%. | I13: Regional net-add history and saturation in NA/Europe.
B14: 10 | C14: Rollover equity | D14: 27% of the equity purchase price (€31.5bn = 34.7% of new equity) at the offer price | E14: 1_Transaction_Summary F49, C49 | F14: ASSUMPTION | G14: The memo's S&U labels it '27%', which is 27% of the equity PURCHASE PRICE, not of the equity cheque. It is ≈88% of the three large holders' combined economic stake (6_IC_Analysis F). It does not change gross IRR (pooled equity) but decides the €59.5bn sponsor cheque. | H14: n/a for IRR; sponsor cheque falls €1.17bn per 1pt of extra rollover. | I14: Founder/Tencent term sheet; tax on rollover; governance asks.
B15: 11 | C15: Option tranches | D15: 4.6m options in 3 tranches (strikes $150 / $350 / $480); €1.6bn cash-out | E15: 1_Transaction_Summary C12:D14 | F15: ESTIMATE | G15: Calibrated so TSM at the Q2 average price reproduces the 2.40m dilutive options in the 6-K EPS note. Real strike schedule is in the 20-F share-based payment note. | H15: Each €100m of extra cash-out ≈ 0.1% of equity cheque. | I15: 20-F SBC note.
B16: 12 | C16: Minimum cash and sweep | D16: €1.5bn minimum; 100% sweep of excess cash to TLA then TLB; notes not swept | E16: Dashboard C11:C13; 4_Debt_Schedule rows 21–24 | F16: ASSUMPTION | G16: Buffer vs €2.6bn accrued royalties. Annual periodicity ignores intra-year royalty seasonality. | H16: Cash is not a return driver once debt is repaid (see 6_IC_Analysis C). | I16: Monthly liquidity sub-model.
... B21: 17 | C21: Dividend-recap module (new) | D21: Switch OFF; recap year FY31; target 4.0x; 100% excess-cash payout; 7.5% coupon; 2.25% fee | E21: 4_Debt_Schedule C73:C79 | F21: ASSUMPTION | G21: All six inputs are my assumptions, labelled in-cell; coupon and fee copy the entry notes/financing fee. Notes are unswept, interest on opening balance, fees charged to equity (not tax-deducted). | H21: See 6_IC_Analysis C. | I21: Market soundings on a post-FY30 recap.

Sheet 8_Change_Log
B1: 8 | Change Log – before / after
B2: Original: Project_Harmony_Spotify_LBO_Model.xlsx (cached values). Updated: this file, recalculated in full on 05-Oct-2026. Base/Upside/Downside outputs are unchanged to the last digit because every edit is switched off or presentational by default.
B4: 1. OUTPUTS – BEFORE vs AFTER
