Workbook

Sheet 0_Control_Panel
A1: VODAFONE IDEA LIMITED (NSE: IDEA) — RESTRUCTURING MODEL v3: CONTROL PANEL
A2: ₹ crore unless stated | Blue = hardcoded input | Black = formula | Red (#C00000) = deficit / breach warning | Steel grey (#2F4F4F) = section header | Model date: 06-Oct-2026 (v3)
A3: v3 (6-Oct-2026 review of v2): anchors refreshed to quarter ended 30-Jun-2026 (results announced 10-Aug-2026) · TWCF cost base reconciled to 3_Proj · "DoT cash deferral" + NPV + cliff test (2_Cap rows 90-115) · liquidation SBI switch default 0 (4_Liq B8) · conversion-price sensitivity (rows 132-152) · new checks 6_Reconciliations R8-R11 · v2→v3 change log: 6_Reconciliations R7 (row 125+). v2 (4-Oct-2026): bridge switch B23 · Plan D · asset-sale row 89 · Plan C s.14 fix · week-10 sensitivity.
A4: 1. RESTRUCTURING SCENARIO SWITCHER
A5: Active scenario (1 = Plan A, 2 = Plan B, 3 = Plan C, 4 = Plan D) | B5: 1
A6: Active scenario name | B6: =CHOOSE(B5,"Plan A: Govt AGR/Spectrum Equity Swap + Deferral","Plan B: Consensual Out-of-Court Bank Haircut (RBI Prudential Framework ICA)","Plan C: Formal CIRP / Liquidation under IBC s.53","Plan D: Strategic Investor / Asset Sale + 12-month DoT Standstill (no Govt conversion)") -> Plan A: Govt AGR/Spectrum Equity Swap + Deferral
A8: 2. MACRO SWITCHES
A9: 5G CapEx switch (1 = On, 0 = Off) | B9: 1
A10: 5G CapEx intensity multiplier (x) | B10: 1
A11: ARPU expansion case (1 = Low, 2 = Base, 3 = High) | B11: 2
A12: ARPU growth p.a. — Low (tariff repair stalls) | B12: 0.04
A13: ARPU growth p.a. — Base (one industry hike per ~18 months) | B13: 0.07
A14: ARPU growth p.a. — High (management plan) | B14: 0.11
A15: Active ARPU growth p.a. | B15: =CHOOSE($B$11,$B$12,$B$13,$B$14) -> 0.07
A16: 5G ARPU premium uplift p.a. (applies if 5G switch = 1) | B16: 0.005
A17: Subscriber churn-reduction switch (1 = On) | B17: 1
A18: Operating-cost rationalisation switch (1 = On) | B18: 1
A19: Default penalty manual override (1 = force +bps on) | B19: 0
A20: Default penalty interest step-up (bps) | B20: 200
A21: Interest mode — bank & SBI facility (1 = Cash-pay, 2 = PIK) | B21: 1
A22: Interest mode — NCDs (1 = Cash-pay, 2 = PIK) | B22: 1
A23: Valuation bridge treatment (1 = Strict, 2 = Middle, 3 = Conservative) | B23: 2
A24: 3. PUBLIC-DISCLOSURE ANCHORS (balance sheet, debt stack, operating run-rate) | C24: Class | D24: In claims (₹ cr) | E24: v3 check | F24: Source / basis
A25: Deferred spectrum payment obligation (DPO) incl. accrued interest | B25: 130299 | C25: Sourced | D25: =B25 -> 130299 | E25: Updated v3 | F25: VIL Q1 FY27 results (quarter ended 30-Jun-2026; announced 10-Aug-2026): deferred payment obligations towards spectrum ₹1,30,299 cr (Free Press Journal, 10-Aug-2026). v2 used the 31-Mar-2026 figure ₹1,27,360 cr. [v3: verified vs public report; primary filing not opened]
A26: AGR dues — nominal, as finalised by DoT committee | B26: 64046 | C26: Sourced | D26: =B26 -> 64046 | E26: Verified | F26: VIL BSE/NSE filing 30-Apr-2026: AGR finalised at ₹64,046 cr as of 31-Dec-2025 (down ₹23,649 cr from ₹87,695 cr).
A27: AGR DPO — carrying value (discounted, Ind AS) | B27: 25759 | C27: Sourced | E27: Updated v3 | F27: VIL Q1 FY27 results (quarter ended 30-Jun-2026): ₹25,759 cr deferred payment obligation towards AGR (Free Press Journal, 10-Aug-2026); used as the Ind AS carrying value of the back-ended schedule. v2: ₹25,254 cr at 31-Mar-2026. [v3: verified vs public report]
A28: Senior secured bank loans (SBI-led consortium) — outstanding | B28: 211 | C28: Sourced | D28: =B28 -> 211 | E28: Verified | F28: Quarter ended 30-Jun-2026; results announced 10-Aug-2026: bank debt ₹211 cr (₹1,926 cr a year earlier). [v3: verified — public reports show bank debt ₹211 cr vs ₹1,926 cr a year earlier]
A29: Non-convertible debentures (secured) | B29: 3300 | C29: Sourced | D29: =B29 -> 3300 | E29: Partly verified | F29: Quarter ended 30-Jun-2026; results announced 10-Aug-2026 — earnings call: ₹3,300 cr NCDs; net debt ₹3,489 cr. [v3: PARTLY verified — ₹3,300 cr + ₹211 cr ties to reported ₹3,708 cr bank & other debt incl. accrued interest; the ₹3,489 cr net-debt figure was not re-verified]
A30: Cash & bank balances | B30: 6558 | C30: Sourced | E30: Verified | F30: Quarter ended 30-Jun-2026; results announced 10-Aug-2026 — Q1 FY27 results: ₹6,558 cr at 30-Jun-2026 (incl. part warrant proceeds). [v3: verified]
A31: Revenue from operations — Q1 FY27 | B31: 11689 | C31: Sourced | E31: Verified | F31: Quarter ended 30-Jun-2026; results announced 10-Aug-2026 — Q1 FY27 results: ₹11,689 cr (+6.0% YoY). [v3: verified]
A32: EBITDA (Ind AS 116) — Q1 FY27 | B32: 5034 | C32: Sourced | E32: Verified | F32: Quarter ended 30-Jun-2026; results announced 10-Aug-2026 — Q1 FY27 results: ₹5,034 cr, 43.1% margin. [v3: verified]
A33: Cash EBITDA (post lease rentals) — Q1 FY27 | B33: 2475 | C33: Sourced | E33: Verified | F33: Quarter ended 30-Jun-2026; results announced 10-Aug-2026 — earnings call: ₹2,475 cr (+13.5% YoY). [v3: verified]
A34: Capex — Q1 FY27 | B34: 1930 | C34: Sourced | E34: Verified | F34: Quarter ended 30-Jun-2026; results announced 10-Aug-2026 — earnings call: ₹1,930 cr (supply-chain constrained). [v3: verified]
A35: Subscribers (mn) — 30-Jun-2026 | B35: 193.1 | C35: Sourced | E35: Verified | F35: Quarter ended 30-Jun-2026; results announced 10-Aug-2026: 193.1 mn (first positive net add quarter since merger). [v3: verified]
A36: Customer ARPU (₹/month, ex-M2M) | B36: 195 | C36: Sourced | E36: Verified | F36: Quarter ended 30-Jun-2026; results announced 10-Aug-2026: ₹195 (+10.2% YoY). [v3: verified]
A37: Government of India shareholding | B37: 0.4899 | C37: Sourced | E37: Partly verified | F37: Post April-2025 conversion of ₹36,950 cr spectrum dues: 48.99%.
A38: Reference share price (₹) | B38: 12.64 | C38: Sourced | E38: Updated v3 (dated) | F38: NSE close 1-Oct-2026 ₹12.64 (ICICI Direct). 5-Oct-2026 intraday ₹12.63–12.74 (Anand Rathi / HDFC Sky) — close not confirmed. 10-Aug-2026 close ₹12.92 (per v3 brief; NOT independently verified). Not a live feed: UPDATE TO LIVE PRICE before circulation.
A39: Market capitalisation at reference price | B39: 136945.6 | C39: Sourced | E39: Updated v3 (3rd party) | F39: Third-party market cap at ₹12.64 as of 1-Oct-2026: ₹1,36,945.6 cr (ICICI Direct / Tickertape). UNVERIFIED vs exchange data.
A40: Shares outstanding (crore) — derived | B40: =$B$39/$B$38 -> 10834.304 | C40: Sourced | E40: Derived; ties to 3rd party | F40: Calc: market cap / price = ~10,834 cr; ties to third-party share count 10,834.3 cr (Tickertape / Yahoo 108.34bn). v2 derived 10,311 cr from a stale price × market cap pair. Replace with the BSE shareholding-pattern count.
A41: Face value / par (₹) — legal floor on issue price | B41: 10 | C41: Sourced | E41: Verified (face value) | F41: Companies Act 2013 s.53 prohibits issue at a discount to par; 2023 and 2025 Govt conversions were at ₹10.
...

Sheet 1_TWCF_13_Week_Liquidity
A1: 1. THIRTEEN-WEEK DIRECT CASH FLOW (TWCF) — LIQUIDITY RUNWAY & ₹40 BN ALERT [v3]
A2: ₹ crore | Direct method (receipts vs disbursements) | Weeks commence Monday 05-Oct-2026 (Q3 FY27) | Breach = closing cash < threshold → red flag
A3: ILLUSTRATIVE ASSUMPTIONS (not disclosed figures): B5 opening cash · B23 spectrum instalment amount · C23 instalment week. Everything in rows 75-82 and 85-121 is conditional on them.
A4: DRIVERS | B4: Value | C4: Week # | D4: Basis
A5: Opening cash — week beginning 05-Oct-2026 | B5: 5800 | D5: ILLUSTRATIVE — MODEL ESTIMATE: Jun-26 ₹6,558 cr less ~₹750 cr Q2 net burn. Replace with treasury position.
A6: First week beginning (Monday) | B6: 46300
A7: QoQ revenue growth (Q1 → Q3 FY27) | B7: 0.025 | D7: Q1 FY27 QoQ was +3.2%.
A8: Q3 FY27E revenue (₹ cr) | B8: ='0_Control_Panel'!$B$31*(1+$B$7)^2 -> 12280.756 | D8: Calc: Q1 × (1+QoQ)^2
A9: Q2 FY27E revenue (base for LF/SUC payable) | B9: ='0_Control_Panel'!$B$31*(1+$B$7) -> 11981.225 | D9: Calc: Q1 × (1+QoQ)
A10: Prepaid share of collections | B10: 0.88 | D10: Prepaid collected upfront at recharge.
A11: Collection efficiency (post-scenario stress) | B11: =$B$12*(1-'0_Control_Panel'!$E$79) -> 0.985 | D11: Calc: 98.5% × (1 − scenario receipts stress)
A12: Base collection efficiency | B12: 0.985
A13: Quarterly tower & site rentals (₹ cr) | B13: =('0_Control_Panel'!$B$32-'0_Control_Panel'!$B$33)*(1+$B$7)^2 -> 2688.5494 | D13: Calc: (EBITDA − cash EBITDA) Q1 × (1+QoQ)^2; paid monthly in advance
A14: Indus Towers share of rentals | B14: 0.7 | D14: MODEL ESTIMATE — balance to other towercos (e.g., Data Infrastructure Trust).
A15: Network power & fuel (% revenue) | B15: 0.11 | D15: Diesel/grid electricity pass-through at sites.
A16: Other network O&M (% revenue) | B16: ='3_Restructuring_Projections'!$C$22-$B$15 -> 0.105 | D16: v3: = 3_Proj C22 (21.5% network opex ex-lease, calibrated to the reported 43.1% EBITDA margin) − B15. v2 input was 6.0% (network 17.0%; total cost 52.4% vs 56.9% in 3_Proj). Check rows 124-137.
A17: Licence fee & SUC (% revenue) — paid quarterly | B17: 0.09 | C17: 2 | D17: LF 8% of AGR + SUC; Q2 dues paid within 15 days of quarter end.
A18: Employee costs (% revenue) — paid monthly | B18: 0.046
A19: SG&A, dealer commissions (% revenue) | B19: 0.118
A20: Interconnect, roaming & other (% revenue) | B20: 0.1
A21: Capex cash disbursements in window (₹ cr) | B21: 3800 | D21: Ericsson / Nokia / Samsung milestone payments.
A22: Vendor deferral (% of capex) — active scenario | B22: ='0_Control_Panel'!$E$78 -> 0.1 | D22: From scenario matrix.
A23: Spectrum DPO instalment falling in window (₹ cr) | B23: 2500 | C23: 10 | D23: ILLUSTRATIVE (amount and week) — MODEL TIMING ESTIMATE — NOT a disclosed date; part of FY27 ₹7,076 cr. Amount × week sensitivity in rows 85-117; reconcile to DoT demand notices.
A24: Restructuring relief effective within window? (1 = Yes) | B24: 0 | D24: If 1 and active scenario has a spectrum moratorium, the instalment is deferred.
A25: NCD coupon in window (₹ cr) | B25: ='0_Control_Panel'!$B$29*'2_Capital_Structure_Waterfall'!$E$18/4 -> 88.6875 | C25: 7 | D25: Calc: NCD × coupon / 4
A26: Bank loan amortisation in window (₹ cr) | B26: ='0_Control_Panel'!$B$28*(1-'0_Control_Panel'!$E$75)*IF(OR('0_Control_Panel'!$E$80>0,'0_Control_Panel'!$B$5=3),0,1) -> 0 | C26: 13 | D26: Calc: existing bank debt (bullet in window)
A27: Restructuring professional fees in window (% of process cost) | B27: 0.25
A28: Warrant / equity proceeds (₹ cr) | B28: 1500 | C28: 8 | D28: MODEL ESTIMATE — balance of promoter warrant subscription (₹1,182 cr received Jun-26).
A29: Committed bank facility drawdown (₹ cr) | B29: 0 | C29: 11 | D29: Set > 0 once SBI-led facility documented.
A30: Minimum liquidity threshold (₹ cr) | B30: ='0_Control_Panel'!$B$49 -> 4000 | D30: From Control Panel (₹40 bn).
A31: v3 checks: cost-base reconciliation vs 3_Proj and 13-week cash margin vs reported cash EBITDA margin → rows 123-140.
A33: WEEKLY GRID
A34: Week # | C34: =1 -> 1 | D34: =C34+1 -> 2 | E34: =D34+1 -> 3 | F34: =E34+1 -> 4 | G34: =F34+1 -> 5 | H34: =G34+1 -> 6 | I34: =H34+1 -> 7 | J34: =I34+1 -> 8 | K34: =J34+1 -> 9 | ... O34: =N34+1 -> 13 | P34: 13-wk Total
A35: Week beginning | C35: =$B$6+7*(C34-1) -> 46300 | D35: =$B$6+7*(D34-1) -> 46307 | E35: =$B$6+7*(E34-1) -> 46314 | F35: =$B$6+7*(F34-1) -> 46321 | G35: =$B$6+7*(G34-1) -> 46328 | H35: =$B$6+7*(H34-1) -> 46335 | I35: =$B$6+7*(I34-1) -> 46342 | J35: =$B$6+7*(J34-1) -> 46349 | ... O35: =$B$6+7*(O34-1) -> 46384
A36: First week of month flag (rent / payroll) | C36: =IF(DAY(C35)<=7,1,0) -> 1 | D36: =IF(DAY(D35)<=7,1,0) -> 0 | E36: =IF(DAY(E35)<=7,1,0) -> 0 | F36: =IF(DAY(F35)<=7,1,0) -> 0 | G36: =IF(DAY(G35)<=7,1,0) -> 1 | H36: =IF(DAY(H35)<=7,1,0) -> 0 | I36: =IF(DAY(I35)<=7,1,0) -> 0 | J36: =IF(DAY(J35)<=7,1,0) -> 0 | ... O36: =IF(DAY(O35)<=7,1,0) -> 0
A37: Collections seasonality factor | C37: 1 | D37: 1.02 | E37: 1.04 | F37: 1.03 | G37: 1.01 | H37: 1 | I37: 0.99 | J37: 0.99 | K37: 1 | L37: 1 | M37: 0.98 | N37: 0.97 | O37: 0.97
A39: OPERATING RECEIPTS
A40: Prepaid recharge collections | C40: =$B$8*$B$10*$B$11/13*C$37 -> 818.843 | D40: =$B$8*$B$10*$B$11/13*D$37 -> 835.21986 | E40: =$B$8*$B$10*$B$11/13*E$37 -> 851.59672 | F40: =$B$8*$B$10*$B$11/13*F$37 -> 843.40829 | G40: =$B$8*$B$10*$B$11/13*G$37 -> 827.03143 | H40: =$B$8*$B$10*$B$11/13*H$37 -> 818.843 | I40: =$B$8*$B$10*$B$11/13*I$37 -> 810.65457 | J40: =$B$8*$B$10*$B$11/13*J$37 -> 810.65457 | ... O40: =$B$8*$B$10*$B$11/13*O$37 -> 794.27771 | P40: =SUM(C40:O40) -> 10644.959
A41: Postpaid, enterprise & wholesale collections | C41: =$B$8*(1-$B$10)*$B$11/13 -> 111.66041 | D41: =$B$8*(1-$B$10)*$B$11/13 -> 111.66041 | E41: =$B$8*(1-$B$10)*$B$11/13 -> 111.66041 | F41: =$B$8*(1-$B$10)*$B$11/13 -> 111.66041 | G41: =$B$8*(1-$B$10)*$B$11/13 -> 111.66041 | H41: =$B$8*(1-$B$10)*$B$11/13 -> 111.66041 | I41: =$B$8*(1-$B$10)*$B$11/13 -> 111.66041 | J41: =$B$8*(1-$B$10)*$B$11/13 -> 111.66041 | ... O41: =$B$8*(1-$B$10)*$B$11/13 -> 111.66041 | P41: =SUM(C41:O41) -> 1451.5853
A42: Total operating receipts | C42: =SUM(C40:C41) -> 930.50341 | D42: =SUM(D40:D41) -> 946.88027 | E42: =SUM(E40:E41) -> 963.25713 | F42: =SUM(F40:F41) -> 955.0687 | G42: =SUM(G40:G41) -> 938.69184 | H42: =SUM(H40:H41) -> 930.50341 | I42: =SUM(I40:I41) -> 922.31498 | J42: =SUM(J40:J41) -> 922.31498 | ... O42: =SUM(O40:O41) -> 905.93812 | P42: =SUM(C42:O42) -> 12096.544
...

Sheet 2_Capital_Structure_Waterfall
A1: 2. CAPITAL STRUCTURE, RESTRUCTURING MECHANICS & DEBT SCHEDULES
A2: ₹ crore | Pre-restructuring stack → scenario haircuts / equity conversion → post-restructuring stack | Cash-pay vs PIK toggles | +200 bps default penalty trigger
A4: A. DEFAULT PENALTY TRIGGER LOGIC
A5: TWCF payment-default flag (closing cash < 0) | B5: ='1_TWCF_13_Week_Liquidity'!$B$79 -> 0
A6: Scenario contractual default (standstill / CIRP) | B6: ='0_Control_Panel'!$E$84 -> 0
A7: Manual override | B7: ='0_Control_Panel'!$B$19 -> 0
A8: PENALTY ACTIVE (1/0) = MAX(above) | B8: =MAX(B5:B7) -> 0
A9: Penalty applied (decimal) | B9: =B8*'0_Control_Panel'!$B$20/10000 -> 0
A12: B. DEBT STACK — PRE- TO POST-RESTRUCTURING (IBC s.53 classification)
A13: Tranche / creditor | B13: IBC s.53 class | C13: Security / status | D13: Face (₹ cr) | E13: Base rate | F13: Penalty | G13: All-in rate | H13: Mode 1=Cash 2=PIK | I13: Annual interest | J13: Cash interest | K13: PIK accrual | L13: Haircut % | M13: Equity conv % | N13: Converted to equity | O13: Written off | P13: Post-deal balance | Q13: Maturity ext (yrs) | R13: Treatment
A14: Statutory — Spectrum DPO (DoT) | B14: 53(1)(e)/(f) Govt dues | C14: Unsecured statutory | D14: ='0_Control_Panel'!$B$25 -> 130299 | E14: ='0_Control_Panel'!$E$73 -> 0.075 | F14: =$B$9*0 -> 0 | G14: =E14+F14 -> 0.075 | H14: ='0_Control_Panel'!$E$74 -> 2 | I14: =P14*G14 -> 7817.94 | J14: =IF(H14=1,I14,0) -> 0 | K14: =IF(H14=2,I14,0) -> 7817.94 | L14: =0 -> 0 | M14: ='0_Control_Panel'!$E$70 -> 0.2 | N14: =D14*M14 -> 26059.8 | O14: =D14*L14 -> 0 | P14: =D14-N14-O14 -> 104239.2 | Q14: =0 -> 0 | R14: Plan A: equity swap + 4-yr moratorium + rate reset
A15: Statutory — AGR dues (nominal, DoT) | B15: 53(1)(e)/(f) Govt dues | C15: Unsecured statutory | D15: ='0_Control_Panel'!$B$26 -> 64046 | E15: 0 | F15: =$B$9*0 -> 0 | G15: =E15+F15 -> 0 | H15: 1 | I15: =P15*G15 -> 0 | J15: =IF(H15=1,I15,0) -> 0 | K15: =IF(H15=2,I15,0) -> 0 | L15: =0 -> 0 | M15: ='0_Control_Panel'!$E$69 -> 0.25 | N15: =D15*M15 -> 16011.5 | O15: =D15*L15 -> 0 | P15: =D15-N15-O15 -> 48034.5 | Q15: =0 -> 0 | R15: Interest-free staggered FY27–FY41; Plan A partial swap
A16: Senior secured bank loans — SBI consortium (existing) | B16: 53(1)(b) Secured FC | C16: First charge, pari passu | D16: ='0_Control_Panel'!$B$28 -> 211 | E16: 0.105 | F16: =$B$9*1 -> 0 | G16: =E16+F16 -> 0.105 | H16: ='0_Control_Panel'!$B$21 -> 1 | I16: =P16*G16 -> 22.155 | J16: =IF(H16=1,I16,0) -> 22.155 | K16: =IF(H16=2,I16,0) -> 0 | L16: ='0_Control_Panel'!$E$75 -> 0 | M16: =0 -> 0 | N16: =D16*M16 -> 0 | O16: =D16*L16 -> 0 | P16: =D16-N16-O16 -> 211 | Q16: ='0_Control_Panel'!$E$80 -> 5 | R16: Plan B haircut 35–50%; +5-yr extension
A17: SBI-led capex facility (pro forma new money, drawn) | B17: 53(1)(b) Secured FC | C17: Pari passu first charge | D17: ='0_Control_Panel'!$B$58*'0_Control_Panel'!$E$83 -> 15000 | E17: 0.1025 | F17: =$B$9*1 -> 0 | G17: =E17+F17 -> 0.1025 | H17: ='0_Control_Panel'!$B$21 -> 1 | I17: =P17*G17 -> 1537.5 | J17: =IF(H17=1,I17,0) -> 1537.5 | K17: =IF(H17=2,I17,0) -> 0 | L17: =0 -> 0 | M17: =0 -> 0 | N17: =D17*M17 -> 0 | O17: =D17*L17 -> 0 | P17: =D17-N17-O17 -> 15000 | Q17: ='0_Control_Panel'!$E$80 -> 5 | R17: New money; drawn FY27; amortises from FY29
A18: Non-convertible debentures (secured) | B18: 53(1)(b) Secured FC | C18: Secured, debenture trustee | D18: ='0_Control_Panel'!$B$29 -> 3300 | E18: 0.1075 | F18: =$B$9*1 -> 0 | G18: =E18+F18 -> 0.1075 | H18: ='0_Control_Panel'!$B$22 -> 1 | I18: =P18*G18 -> 354.75 | J18: =IF(H18=1,I18,0) -> 354.75 | K18: =IF(H18=2,I18,0) -> 0 | L18: ='0_Control_Panel'!$E$76 -> 0 | M18: =0 -> 0 | N18: =D18*M18 -> 0 | O18: =D18*L18 -> 0 | P18: =D18-N18-O18 -> 3300 | Q18: ='0_Control_Panel'!$E$80 -> 5 | R18: Bullet FY29; Plan B 25% haircut
A19: Lease liabilities — Indus Towers & other towercos | B19: 53(1)(f) Operational | C19: Unsecured; Indus security pkg | D19: ='0_Control_Panel'!$B$52 -> 19500 | E19: 0.095 | F19: =$B$9*0 -> 0 | G19: =E19+F19 -> 0.095 | H19: 1 | I19: =P19*G19 -> 1852.5 | J19: =IF(H19=1,I19,0) -> 1852.5 | K19: =IF(H19=2,I19,0) -> 0 | L19: =0 -> 0 | M19: =0 -> 0 | N19: =D19*M19 -> 0 | O19: =D19*L19 -> 0 | P19: =D19-N19-O19 -> 19500 | Q19: =0 -> 0 | R19: Ind AS 116; reinstated (critical supplier)
A20: Trade payables — Indus Towers (MSA) | B20: 53(1)(f) Operational | C20: Unsecured | D20: ='0_Control_Panel'!$B$53 -> 2800 | E20: 0 | F20: =$B$9*0 -> 0 | G20: =E20+F20 -> 0 | H20: 1 | I20: =P20*G20 -> 0 | J20: =IF(H20=1,I20,0) -> 0 | K20: =IF(H20=2,I20,0) -> 0 | L20: =0 -> 0 | M20: =0 -> 0 | N20: =D20*M20 -> 0 | O20: =D20*L20 -> 0 | P20: =D20-N20-O20 -> 2800 | Q20: =0 -> 0 | R20: Paid in full — critical vendor
A21: Trade payables — Ericsson / Nokia / Samsung | B21: 53(1)(f) Operational | C21: Unsecured | D21: ='0_Control_Panel'!$B$54 -> 5500 | E21: 0 | F21: =$B$9*0 -> 0 | G21: =E21+F21 -> 0 | H21: 1 | I21: =P21*G21 -> 0 | J21: =IF(H21=1,I21,0) -> 0 | K21: =IF(H21=2,I21,0) -> 0 | L21: ='0_Control_Panel'!$E$77 -> 0 | M21: =0 -> 0 | N21: =D21*M21 -> 0 | O21: =D21*L21 -> 0 | P21: =D21-N21-O21 -> 5500 | Q21: =0 -> 0 | R21: Plan B 15% haircut / deferral
A22: Trade payables — other operational creditors | B22: 53(1)(f) Operational | C22: Unsecured | D22: ='0_Control_Panel'!$B$55 -> 3200 | E22: 0 | F22: =$B$9*0 -> 0 | G22: =E22+F22 -> 0 | H22: 1 | I22: =P22*G22 -> 0 | J22: =IF(H22=1,I22,0) -> 0 | K22: =IF(H22=2,I22,0) -> 0 | L22: ='0_Control_Panel'!$E$77 -> 0 | M22: =0 -> 0 | N22: =D22*M22 -> 0 | O22: =D22*L22 -> 0 | P22: =D22-N22-O22 -> 3200 | Q22: =0 -> 0 | R22: Plan B 15% haircut
A23: Other liabilities & provisions | B23: 53(1)(f) Remaining | C23: Unsecured | D23: ='0_Control_Panel'!$B$57 -> 22000 | E23: 0 | F23: =$B$9*0 -> 0 | G23: =E23+F23 -> 0 | H23: 1 | I23: =P23*G23 -> 0 | J23: =IF(H23=1,I23,0) -> 0 | K23: =IF(H23=2,I23,0) -> 0 | L23: =0 -> 0 | M23: =0 -> 0 | N23: =D23*M23 -> 0 | O23: =D23*L23 -> 0 | P23: =D23-N23-O23 -> 22000 | Q23: =0 -> 0 | R23: Reinstated
A24: TOTAL CLAIMS (AGR at nominal) | D24: =SUM(D14:D23) -> 265856 | I24: =SUM(I14:I23) -> 11584.845 | J24: =SUM(J14:J23) -> 3766.905 | K24: =SUM(K14:K23) -> 7817.94 | N24: =SUM(N14:N23) -> 42071.3 | O24: =SUM(O14:O23) -> 0 | P24: =SUM(P14:P23) -> 223784.7
A25: of which statutory Government dues | D25: =D14+D15 -> 194345 | N25: =N14+N15 -> 42071.3 | O25: =O14+O15 -> 0 | P25: =P14+P15 -> 152273.7
A26: of which funded financial debt (bank + SBI + NCD) | D26: =D16+D17+D18 -> 18511 | N26: =N16+N17+N18 -> 0 | O26: =O16+O17+O18 -> 0 | P26: =P16+P17+P18 -> 18511
A27: of which operational creditors (lease + trade + other) | D27: =D19+D20+D21+D22+D23 -> 53000 | N27: =N19+N20+N21+N22+N23 -> 0 | O27: =O19+O20+O21+O22+O23 -> 0 | P27: =P19+P20+P21+P22+P23 -> 53000
A28: Statutory dues as % of total claims | D28: =D25/D24 -> 0.73101604 | P28: =P25/P24 -> 0.68044732
A29: Haircut gain recognised (bank + NCD + vendors) — P&L exceptional | O29: =O16+O18+O21+O22 -> 0
A30: Plan B bank haircut quantum vs total claims (materiality test) | O30: =IFERROR(O16/D24,0) -> 0
A32: C. PRO FORMA OWNERSHIP & DILUTION | B32: Crore shares | C32: % pre | D32: % post
A33: Shares outstanding — pre-deal | B33: ='0_Control_Panel'!$B$40 -> 10834.304
A34: Government of India — existing | B34: =B33*'0_Control_Panel'!$B$37 -> 5307.7254 | C34: =B34/B33 -> 0.4899 | D34: =(B34+B36)/B38 -> 0.5840404
A35: Promoters (ABG / Vodafone) & public — existing | B35: =B33-B34 -> 5526.5784 | C35: =B35/B33 -> 0.5101 | D35: =B35/B38 -> 0.33923217
A36: New shares — statutory dues conversion (to Govt) | B36: =(N14+N15)/'0_Control_Panel'!$E$71 -> 4207.13
A37: New shares — new-money equity (promoters / QIP) | B37: ='0_Control_Panel'!$E$81/'0_Control_Panel'!$E$82 -> 1250 | D37: =B37/B38 -> 0.076727439
A38: Shares outstanding — post-deal (fully diluted) | B38: =B33+B36+B37 -> 16291.434
A39: Government economic stake — post | B39: =(B34+B36)/B38 -> 0.5840404
A40: Government voting-stake cap | B40: ='0_Control_Panel'!$E$88 -> 0.49
A41: Excess Govt shares to be issued as non-voting OCRPS (crore) | B41: =MAX(0,(B34+B36)-B40*B38) -> 1532.0529
A42: Dilution to existing non-Govt holders (%) | B42: =1-(B35/B38)/(B35/B33) -> 0.33496929
A44: D. ANNUAL DEBT SCHEDULES (feed 3_Restructuring_Projections)
C45: Pre-deal | D45: FY27E | E45: FY28E | F45: FY29E | G45: FY30E | H45: FY31E
...

Sheet 3_Restructuring_Projections
A1: 3. FIVE-YEAR INTEGRATED 3-STATEMENT PROJECTIONS (FY27E–FY31E) + GOING-CONCERN DCF
A2: ₹ crore | Opening column = Q1 FY27 annualised run-rate / pro forma opening balance sheet | Fiscal year ending 31-March | Liquidity facility auto-draws to hold minimum cash
A4: ₹ crore | B4: Driver | C4: Run-rate / Open | D4: FY27E | E4: FY28E | F4: FY29E | G4: FY30E | H4: FY31E
A5: Year index | C5: 0 | D5: =C5+1 -> 1 | E5: =D5+1 -> 2 | F5: =E5+1 -> 3 | G5: =F5+1 -> 4 | H5: =G5+1 -> 5
A6: OPERATING DRIVERS
A7: Monthly churn | B7: 0.0005 | C7: 0.038 | D7: =MAX($B$8,C7-$B$7*'0_Control_Panel'!$B$17) -> 0.0375 | E7: =MAX($B$8,D7-$B$7*'0_Control_Panel'!$B$17) -> 0.037 | F7: =MAX($B$8,E7-$B$7*'0_Control_Panel'!$B$17) -> 0.0365 | G7: =MAX($B$8,F7-$B$7*'0_Control_Panel'!$B$17) -> 0.036 | H7: =MAX($B$8,G7-$B$7*'0_Control_Panel'!$B$17) -> 0.0355 | I7: Driver col = annual reduction in monthly churn (pp) when switch on; floor below.
A8: Monthly churn floor | B8: 0.035
A9: Monthly gross-add rate (% of opening base) | B9: 0.0385 | D9: =$B$9 -> 0.0385 | E9: =$B$9 -> 0.0385 | F9: =$B$9 -> 0.0385 | G9: =$B$9 -> 0.0385 | H9: =$B$9 -> 0.0385
A10: Subscribers — opening (mn) | D10: =C12 -> 193.1 | E10: =D12 -> 195.4172 | F10: =E12 -> 198.93471 | G10: =F12 -> 203.70914 | H10: =G12 -> 209.82042
A11: Net adds (mn) | D11: =D10*(D9-D7)*12 -> 2.3172 | E11: =E10*(E9-E7)*12 -> 3.5175096 | F11: =F10*(F9-F7)*12 -> 4.774433 | G11: =G10*(G9-G7)*12 -> 6.1112743 | H11: =H10*(H9-H7)*12 -> 7.553535
A12: Subscribers — closing (mn) | C12: ='0_Control_Panel'!$B$35 -> 193.1 | D12: =D10+D11 -> 195.4172 | E12: =E10+E11 -> 198.93471 | F12: =F10+F11 -> 203.70914 | G12: =G10+G11 -> 209.82042 | H12: =H10+H11 -> 217.37395
A13: Average subscribers (mn) | D13: =AVERAGE(D10,D12) -> 194.2586 | E13: =AVERAGE(E10,E12) -> 197.17595 | F13: =AVERAGE(F10,F12) -> 201.32193 | G13: =AVERAGE(G10,G12) -> 206.76478 | H13: =AVERAGE(H10,H12) -> 213.59718
A14: ARPU growth (active case) | D14: ='0_Control_Panel'!$B$15 -> 0.07 | E14: ='0_Control_Panel'!$B$15 -> 0.07 | F14: ='0_Control_Panel'!$B$15 -> 0.07 | G14: ='0_Control_Panel'!$B$15 -> 0.07 | H14: ='0_Control_Panel'!$B$15 -> 0.07
A15: 5G ARPU premium | D15: ='0_Control_Panel'!$B$9*'0_Control_Panel'!$B$16 -> 0.005 | E15: ='0_Control_Panel'!$B$9*'0_Control_Panel'!$B$16 -> 0.005 | F15: ='0_Control_Panel'!$B$9*'0_Control_Panel'!$B$16 -> 0.005 | G15: ='0_Control_Panel'!$B$9*'0_Control_Panel'!$B$16 -> 0.005 | H15: ='0_Control_Panel'!$B$9*'0_Control_Panel'!$B$16 -> 0.005
A16: ARPU (₹/month) | C16: ='0_Control_Panel'!$B$36 -> 195 | D16: =C16*(1+D14+D15) -> 209.625 | E16: =D16*(1+E14+E15) -> 225.34688 | F16: =E16*(1+F14+F15) -> 242.24789 | G16: =F16*(1+G14+G15) -> 260.41648 | H16: =G16*(1+H14+H15) -> 279.94772
A17: Mobile service revenue | C17: ='0_Control_Panel'!$B$35*'0_Control_Panel'!$B$36*12/10 -> 45185.4 | D17: =D13*D16*12/10 -> 48865.751 | E17: =E13*E16*12/10 -> 53319.582 | F17: =F13*F16*12/10 -> 58523.774 | G17: =G13*G16*12/10 -> 64613.948 | H17: =H13*H16*12/10 -> 71755.253 | I17: mn subs × ₹/month × 12 ÷ 10 = ₹ crore
A18: Other revenue (enterprise, M2M, wholesale) — % of mobile | B18: =C18/C17 -> 0.034759015 | C18: ='0_Control_Panel'!$B$31*4-C17 -> 1570.6 | D18: =D17*$B$18 -> 1698.5254 | E18: =E17*$B$18 -> 1853.3362 | F18: =F17*$B$18 -> 2034.2288 | G18: =G17*$B$18 -> 2245.9172 | H18: =H17*$B$18 -> 2494.1419
A19: TOTAL REVENUE | C19: =C17+C18 -> 46756 | D19: =D17+D18 -> 50564.276 | E19: =E17+E18 -> 55172.918 | F19: =F17+F18 -> 60558.003 | G19: =G17+G18 -> 66859.865 | H19: =H17+H18 -> 74249.395 | I19: Run-rate = Q1 FY27 × 4 = ₹46,756 cr
A20: Revenue growth | D20: =D19/C19-1 -> 0.08145 | E20: =E19/D19-1 -> 0.091144235 | F20: =F19/E19-1 -> 0.097603766 | G20: =G19/F19-1 -> 0.10406324 | H20: =H19/G19-1 -> 0.11052266
A21: COST STRUCTURE (% of revenue) — driver column = annual rationalisation step if switch on
A22: Network opex ex-lease (power, fuel, O&M) | B22: 0.006 | C22: 0.215 | D22: =C22-$B$22*'0_Control_Panel'!$B$18 -> 0.209 | E22: =D22-$B$22*'0_Control_Panel'!$B$18 -> 0.203 | F22: =E22-$B$22*'0_Control_Panel'!$B$18 -> 0.197 | G22: =F22-$B$22*'0_Control_Panel'!$B$18 -> 0.191 | H22: =G22-$B$22*'0_Control_Panel'!$B$18 -> 0.185
A23: Licence fee & SUC | B23: 0 | C23: 0.09 | D23: =C23-$B$23*'0_Control_Panel'!$B$18 -> 0.09 | E23: =D23-$B$23*'0_Control_Panel'!$B$18 -> 0.09 | F23: =E23-$B$23*'0_Control_Panel'!$B$18 -> 0.09 | G23: =F23-$B$23*'0_Control_Panel'!$B$18 -> 0.09 | H23: =G23-$B$23*'0_Control_Panel'!$B$18 -> 0.09
A24: Employee | B24: 0.001 | C24: 0.046 | D24: =C24-$B$24*'0_Control_Panel'!$B$18 -> 0.045 | E24: =D24-$B$24*'0_Control_Panel'!$B$18 -> 0.044 | F24: =E24-$B$24*'0_Control_Panel'!$B$18 -> 0.043 | G24: =F24-$B$24*'0_Control_Panel'!$B$18 -> 0.042 | H24: =G24-$B$24*'0_Control_Panel'!$B$18 -> 0.041
A25: SG&A & customer acquisition | B25: 0.004 | C25: 0.118 | D25: =C25-$B$25*'0_Control_Panel'!$B$18 -> 0.114 | E25: =D25-$B$25*'0_Control_Panel'!$B$18 -> 0.11 | F25: =E25-$B$25*'0_Control_Panel'!$B$18 -> 0.106 | G25: =F25-$B$25*'0_Control_Panel'!$B$18 -> 0.102 | H25: =G25-$B$25*'0_Control_Panel'!$B$18 -> 0.098
A26: Interconnect, roaming & other | B26: 0.002 | C26: 0.1 | D26: =C26-$B$26*'0_Control_Panel'!$B$18 -> 0.098 | E26: =D26-$B$26*'0_Control_Panel'!$B$18 -> 0.096 | F26: =E26-$B$26*'0_Control_Panel'!$B$18 -> 0.094 | G26: =F26-$B$26*'0_Control_Panel'!$B$18 -> 0.092 | H26: =G26-$B$26*'0_Control_Panel'!$B$18 -> 0.09
A27: Total opex % (ex-lease) | C27: =SUM(C22:C26) -> 0.569 | D27: =SUM(D22:D26) -> 0.556 | E27: =SUM(E22:E26) -> 0.543 | F27: =SUM(F22:F26) -> 0.53 | G27: =SUM(G22:G26) -> 0.517 | H27: =SUM(H22:H26) -> 0.504
A28: INCOME STATEMENT
A29: Revenue | C29: =C19 -> 46756 | D29: =D19 -> 50564.276 | E29: =E19 -> 55172.918 | F29: =F19 -> 60558.003 | G29: =G19 -> 66859.865 | H29: =H19 -> 74249.395
A30: Network opex | C30: =-C19*C22 -> -10052.54 | D30: =-D19*D22 -> -10567.934 | E30: =-E19*E22 -> -11200.102 | F30: =-F19*F22 -> -11929.927 | G30: =-G19*G22 -> -12770.234 | H30: =-H19*H22 -> -13736.138
A31: Licence fee & SUC | C31: =-C19*C23 -> -4208.04 | D31: =-D19*D23 -> -4550.7849 | E31: =-E19*E23 -> -4965.5627 | F31: =-F19*F23 -> -5450.2203 | G31: =-G19*G23 -> -6017.3879 | H31: =-H19*H23 -> -6682.4456
A32: Employee costs | C32: =-C19*C24 -> -2150.776 | D32: =-D19*D24 -> -2275.3924 | E32: =-E19*E24 -> -2427.6084 | F32: =-F19*F24 -> -2603.9941 | G32: =-G19*G24 -> -2808.1143 | H32: =-H19*H24 -> -3044.2252
A33: SG&A | C33: =-C19*C25 -> -5517.208 | D33: =-D19*D25 -> -5764.3275 | E33: =-E19*E25 -> -6069.021 | F33: =-F19*F25 -> -6419.1483 | G33: =-G19*G25 -> -6819.7062 | H33: =-H19*H25 -> -7276.4407
A34: Interconnect & other | C34: =-C19*C26 -> -4675.6 | D34: =-D19*D26 -> -4955.2991 | E34: =-E19*E26 -> -5296.6002 | F34: =-F19*F26 -> -5692.4523 | G34: =-G19*G26 -> -6151.1076 | H34: =-H19*H26 -> -6682.4456
A35: EBITDA (Ind AS 116) | C35: =SUM(C29:C34) -> 20151.836 | D35: =SUM(D29:D34) -> 22450.539 | E35: =SUM(E29:E34) -> 25214.024 | F35: =SUM(F29:F34) -> 28462.261 | G35: =SUM(G29:G34) -> 32293.315 | H35: =SUM(H29:H34) -> 36827.7 | I35: Check: run-rate ≈ ₹5,034 cr × 4
A36: EBITDA margin | C36: =C35/C19 -> 0.431 | D36: =D35/D19 -> 0.444 | E36: =E35/E19 -> 0.457 | F36: =F35/F19 -> 0.47 | G36: =G35/G19 -> 0.483 | H36: =H35/H19 -> 0.496
A37: Lease-rental growth (sites; +5G densification if on) | B37: 0.03 | D37: =$B$37+'0_Control_Panel'!$B$9*0.02 -> 0.05 | E37: =$B$37+'0_Control_Panel'!$B$9*0.02 -> 0.05 | F37: =$B$37+'0_Control_Panel'!$B$9*0.02 -> 0.05 | G37: =$B$37+'0_Control_Panel'!$B$9*0.02 -> 0.05 | H37: =$B$37+'0_Control_Panel'!$B$9*0.02 -> 0.05
A38: Lease rentals paid (Indus Towers & others) | C38: =('0_Control_Panel'!$B$32-'0_Control_Panel'!$B$33)*4 -> 10236 | D38: =C38*(1+D37) -> 10747.8 | E38: =D38*(1+E37) -> 11285.19 | F38: =E38*(1+F37) -> 11849.45 | G38: =F38*(1+G37) -> 12441.922 | H38: =G38*(1+H37) -> 13064.018
A39: CASH EBITDA (EBITDA − lease rentals) | C39: =C35-C38 -> 9915.836 | D39: =D35-D38 -> 11702.739 | E39: =E35-E38 -> 13928.834 | F39: =F35-F38 -> 16612.812 | G39: =G35-G38 -> 19851.393 | H39: =H35-H38 -> 23763.682 | I39: Run-rate ≈ ₹2,475 cr × 4. Management targets ~3x in three years.
A40: Depreciation — PP&E | B40: 0.22 | D40: =-C67*$B$40 -> -8360 | E40: =-D67*$B$40 -> -9380.8 | F40: =-E67*$B$40 -> -10727.024 | G40: =-F67*$B$40 -> -11777.079 | H40: =-G67*$B$40 -> -11826.121
A41: Amortisation — spectrum & intangibles | B41: 0.09 | D41: =-C68*$B$41 -> -8550 | E41: =-D68*$B$41 -> -7780.5 | F41: =-E68*$B$41 -> -7080.255 | G41: =-F68*$B$41 -> -6443.032 | H41: =-G68*$B$41 -> -5863.1592
...

Sheet 4_Liquidation_Waterfall
A1: 4. LIQUIDATION ANALYSIS — ASSET RECOVERY & IBC SECTION 53 DISTRIBUTION WATERFALL
A2: ₹ crore | Liquidation commencement assumed at end of 13-week window | Statutory hierarchy per Insolvency and Bankruptcy Code, 2016, s.53(1)(a)–(h)
A4: A. SWITCHES
A5: Recovery case (1 = Low, 2 = Mid, 3 = High) | B5: 2 | H5: Mid used for memo.
A6: Spectrum right-to-use included in liquidation estate (1/0) | B6: 1 | H6: Legally contested: DoT position is that spectrum is a sovereign resource; Aircel/RCom CIRPs show transfer is conditional on clearing DoT dues.
A7: Treat Govt dues as secured — Rainbow Papers (SC, 2022) sensitivity (1/0) | B7: 0 | H7: If 1, statutory dues rank pari passu with secured creditors in s.53(1)(b).
A8: Include pro forma SBI facility in secured claims (1/0) | B8: 0 | H8: v3 default 0 for the "today" comparison: the ₹15,000 cr pro forma SBI facility is not drawn today, and v2 counted it as a secured claim with no matching asset (understating the Govt recovery). Set 1 for the failure-after-drawdown case. Both Govt recoveries are shown live in block F below (rows 55-75).
A10: B. ASSET-BY-ASSET RECOVERY SCHEDULE
A11: Asset | B11: Book value | C11: Low % | D11: Mid % | E11: High % | F11: Selected % | G11: Proceeds | H11: Recovery rationale
A12: Spectrum right-to-use (all bands, incl. 5G 3.3 GHz / 26 GHz) | B12: ='0_Control_Panel'!$B$62*$B$6 -> 95000 | C12: 0.25 | D12: 0.35 | E12: 0.45 | F12: =CHOOSE($B$5,C12,D12,E12) -> 0.35 | G12: =B12*F12 -> 33250 | H12: Forced sale to Jio/Airtel only (two bidders); DoT may cancel licence/reclaim; buyer assumes DoT dues.
A13: Network PP&E (RAN, microwave, fibre, core) | B13: ='0_Control_Panel'!$B$61 -> 38000 | C13: 0.1 | D13: 0.15 | E13: 0.2 | F13: =CHOOSE($B$5,C13,D13,E13) -> 0.15 | G13: =B13*F13 -> 5700 | H13: Vendor-locked radio equipment; scrap/redeploy value; fibre sells better.
A14: Right-of-use assets (tower leases) | B14: ='0_Control_Panel'!$B$63 -> 15000 | C14: 0 | D14: 0 | E14: 0.02 | F14: =CHOOSE($B$5,C14,D14,E14) -> 0 | G14: =B14*F14 -> 0 | H14: Leases terminate on liquidation; Indus re-lets tenancy.
A15: Cash (min of 13-week TWCF, floored at nil) | B15: =MAX(0,'1_TWCF_13_Week_Liquidity'!$B$75) -> 3000.0279 | C15: 1 | D15: 1 | E15: 1 | F15: =CHOOSE($B$5,C15,D15,E15) -> 1 | G15: =B15*F15 -> 3000.0279 | H15: Encumbrance-free cash at liquidation commencement.
A16: Trade receivables | B16: ='0_Control_Panel'!$B$59 -> 2400 | C16: 0.5 | D16: 0.6 | E16: 0.7 | F16: =CHOOSE($B$5,C16,D16,E16) -> 0.6 | G16: =B16*F16 -> 1440 | H16: Enterprise receivables; prepaid has none.
A17: Other current assets (GST input credits, deposits, refunds) | B17: ='0_Control_Panel'!$B$60 -> 14500 | C17: 0.15 | D17: 0.25 | E17: 0.35 | F17: =CHOOSE($B$5,C17,D17,E17) -> 0.25 | G17: =B17*F17 -> 3625 | H17: GST ITC monetisable only partially; refunds slow.
A18: GROSS LIQUIDATION PROCEEDS | B18: =SUM(B12:B17) -> 167900.03 | F18: =G18/B18 -> 0.28001799 | G18: =SUM(G12:G17) -> 47015.028
A19: Low / High proceeds (memo) | C19: =SUMPRODUCT(B12:B17,C12:C17) -> 33925.028 | E19: =SUMPRODUCT(B12:B17,E12:E17) -> 60405.028
A21: C. IBC SECTION 53 DISTRIBUTION WATERFALL
A22: Priority tier | B22: Claim | C22: Available | D22: Recovered | E22: Recovery % | F22: Shortfall | H22: Composition / legal basis
A23: Inputs: workmen dues (24 months) | B23: 150
A24: Inputs: employee wages (12 months, non-workmen) | B24: 700
A25: Inputs: Govt dues falling in 2 yrs preceding (s.53(1)(e)) — calc | B25: ='0_Control_Panel'!$B$42+'0_Control_Panel'!$B$43+2*'0_Control_Panel'!$B$47+'1_TWCF_13_Week_Liquidity'!$B$9*'1_TWCF_13_Week_Liquidity'!$B$17 -> 23402.31
A26: Inputs: total statutory Govt claims (spectrum DPO + AGR nominal) | B26: ='0_Control_Panel'!$B$25+'0_Control_Panel'!$B$26 -> 194345
A27: Inputs: secured financial creditors (bank + NCD + SBI pro forma) | B27: ='0_Control_Panel'!$B$28+'0_Control_Panel'!$B$29+'0_Control_Panel'!$B$58*'0_Control_Panel'!$B$83*$B$8 -> 3511 | H27: SBI pro forma drawn at Plan A draw % (failure after drawdown).
A28: Inputs: operational creditors (lease + trade + other) | B28: ='0_Control_Panel'!$B$52+'0_Control_Panel'!$B$56+'0_Control_Panel'!$B$57 -> 53000
A30: s.53(1)(a) — CIRP & liquidation costs | B30: ='0_Control_Panel'!$D$85 -> 2500 | C30: =$G$18 -> 47015.028 | D30: =MIN(B30,C30) -> 2500 | E30: =IFERROR(D30/B30,0) -> 1 | F30: =B30-D30 -> 0 | H30: IRP/RP & liquidator fees, interim finance, asset preservation.
A31: s.53(1)(b) — Workmen (24m) + secured creditors relinquishing security | B31: =$B$23+$B$27+$B$7*$B$26 -> 3661 | C31: =C30-D30 -> 44515.028 | D31: =MIN(B31,C31) -> 3661 | E31: =IFERROR(D31/B31,0) -> 1 | F31: =B31-D31 -> 0 | H31: Bank, NCD, SBI facility pari passu with workmen; + Govt if Rainbow switch.
A32: s.53(1)(c) — Employee wages (12 months) | B32: =$B$24 -> 700 | C32: =C31-D31 -> 40854.028 | D32: =MIN(B32,C32) -> 700 | E32: =IFERROR(D32/B32,0) -> 1 | F32: =B32-D32 -> 0
A33: s.53(1)(d) — Unsecured financial creditors | B33: =0 -> 0 | C33: =C32-D32 -> 40154.028 | D33: =MIN(B33,C33) -> 0 | E33: =IFERROR(D33/B33,0) -> 0 | F33: =B33-D33 -> 0 | H33: None material.
A34: s.53(1)(e) — Govt dues (2 yrs preceding) + secured unpaid post-enforcement | B34: =$B$25*(1-$B$7) -> 23402.31 | C34: =C33-D33 -> 40154.028 | D34: =MIN(B34,C34) -> 23402.31 | E34: =IFERROR(D34/B34,0) -> 1 | F34: =B34-D34 -> 0 | H34: Spectrum FY27–28 instalments, AGR, current LF/SUC.
A35: s.53(1)(f) — Remaining debts & dues (balance Govt + operational creditors) | B35: =($B$26-$B$25)*(1-$B$7)+$B$28 -> 223942.69 | C35: =C34-D34 -> 16751.718 | D35: =MIN(B35,C35) -> 16751.718 | E35: =IFERROR(D35/B35,0) -> 0.074803592 | F35: =B35-D35 -> 207190.97 | H35: Indus Towers, Ericsson/Nokia/Samsung, lease claims, balance DoT dues.
A36: s.53(1)(g)–(h) — Preference & equity shareholders | B36: =0 -> 0 | C36: =C35-D35 -> 0 | D36: =C36 -> 0 | E36: =IFERROR(D36/B36,0) -> 0 | F36: =B36-D36 -> 0 | H36: Residual only.
A37: TOTAL | B37: =SUM(B30:B36) -> 254206 | D37: =SUM(D30:D36) -> 47015.028 | E37: =D37/B37 -> 0.18494854 | F37: =SUM(F30:F36) -> 207190.97
A39: D. RECOVERY BY CREDITOR CLASS — LIQUIDATION vs GOING CONCERN
A40: Creditor class | B40: Claim | C40: Liquidation ₹ | D40: Liquidation % | E40: Plan A (GC) % | F40: Plan B % | G40: Δ Plan A vs Liq (pp) | H40: Comment
A41: Secured financial creditors (SBI consortium, NCD holders) | B41: =$B$27 -> 3511 | C41: =B41*E31 -> 3511 | D41: =IFERROR(C41/B41,0) -> 1 | E41: =1 -> 1 | F41: =1-('0_Control_Panel'!$B$28*'0_Control_Panel'!$C$75+'0_Control_Panel'!$B$29*'0_Control_Panel'!$C$76)/('0_Control_Panel'!$B$28+'0_Control_Panel'!$B$29) -> 0.74098547 | G41: =(E41-D41)*100 -> 0 | H41: =IF($B$6=1,"Conditional: banks are NOT impaired only IF spectrum is in the estate (B6 = 1, recovered at "&TEXT($F$12,"0%")&" of book) — s.53 then ranks them 2nd and liquidation covers them. If spectrum is excluded and the ₹15,000 cr SBI facility is counted, secured lenders recover about "&TEXT('6_Reconciliations'!$C$94,"0%")&" (6_Reconciliations R6 snapshot).","Spectrum EXCLUDED (B6 = 0): secured lenders recover "&TEXT($D$41,"0%")&" live — banks ARE impaired in this case; see R6 for the SBI-facility variants.") -> Conditional: banks are NOT impaired only IF spectrum is in the estate (B6 = 1, recovered at 35% of book) — s.53 then ranks them 2nd and liquidation covers them. If spectrum is excluded and the ₹15,000 cr SBI facility is counted, secured lenders recover about 60% (6_Reconciliations R6 snapshot).
A42: Government of India — DoT statutory dues | B42: =$B$26 -> 194345 | C42: =IF($B$7=1,$B$26*E31,D34+(B42-$B$25)*E35) -> 36189.438 | D42: =IFERROR(C42/B42,0) -> 0.18621234 | E42: ='3_Restructuring_Projections'!$C$129 -> 0.51241554 | F42: ='3_Restructuring_Projections'!$C$129 -> 0.51241554 | G42: =(E42-D42)*100 -> 32.620319 | H42: The fulcrum creditor: GC value accrues overwhelmingly to the Govt.
A43: Indus Towers (lease + MSA payables) | B43: ='0_Control_Panel'!$B$52+'0_Control_Panel'!$B$53 -> 22300 | C43: =B43*E35 -> 1668.1201 | D43: =IFERROR(C43/B43,0) -> 0.074803592 | E43: =1 -> 1 | F43: =1 -> 1 | G43: =(E43-D43)*100 -> 92.519641 | H43: Critical supplier; paid in full in GC plans.
A44: Network vendors (Ericsson / Nokia / Samsung) | B44: ='0_Control_Panel'!$B$54 -> 5500 | C44: =B44*E35 -> 411.41976 | D44: =IFERROR(C44/B44,0) -> 0.074803592 | E44: =1 -> 1 | F44: =1-'0_Control_Panel'!$C$77 -> 0.85 | G44: =(E44-D44)*100 -> 92.519641
A45: Other operational creditors & provisions | B45: ='0_Control_Panel'!$B$55+'0_Control_Panel'!$B$57 -> 25200 | C45: =B45*E35 -> 1885.0505 | D45: =IFERROR(C45/B45,0) -> 0.074803592 | E45: =1 -> 1 | F45: =1-'0_Control_Panel'!$C$77*'0_Control_Panel'!$B$55/('0_Control_Panel'!$B$55+'0_Control_Panel'!$B$57) -> 0.98095238 | G45: =(E45-D45)*100 -> 92.519641
...

Sheet 5_Logic_Map
A1: MODEL LOGIC MAP — KEY CELLS, FORMULAS & FLOW (v3)
A2: Read with the Control Panel and 6_Reconciliations R7 (change log). Formulas shown as written in the workbook.
A4: Sheet | B4: Key cell | C4: Logic
A5: Control Panel | B5: 0_Control_Panel!$B$5 | C5: Master scenario switch (1 = Plan A, 2 = Plan B, 3 = Plan C, 4 = Plan D). Matrix column E = CHOOSE($B$5, B, C, D, F) — Plan D sits in column F.
A6: Control Panel | B6: 0_Control_Panel!$E$71 | C6: Conversion price = MAX(CHOOSE(scenario), par ₹10) — par floor under Companies Act s.53.
A7: Control Panel | B7: 0_Control_Panel!$B$15 | C7: Active ARPU growth = CHOOSE(ARPU case, Low, Base, High).
A8: TWCF | B8: 1_TWCF_13_Week_Liquidity!$B$11 | C8: Collection efficiency = 98.5% × (1 − scenario receipts stress).
A9: TWCF | B9: 1_TWCF_13_Week_Liquidity!C45 | C9: Indus rent = −IF(first week of month, quarterly rentals × Indus share / 3, 0).
A10: TWCF | B10: 1_TWCF_13_Week_Liquidity!C58 | C10: Spectrum instalment = −IF(week = due week, amount × (1 − relief_flag × (moratorium>0)), 0).
A11: TWCF | B11: 1_TWCF_13_Week_Liquidity!C71 | C11: Alert = IF(close<0,"DEFAULT",IF(close<threshold,"BREACH","OK")); red conditional format.
A12: Capital Structure | B12: 2_Capital_Structure_Waterfall!$B$8 | C12: Penalty active = MAX(TWCF payment default, scenario default, manual override); +bps feeds bank/SBI/NCD all-in rate.
A13: Capital Structure | B13: 2_Capital_Structure_Waterfall!P14 | C13: Post-deal balance = Face − Converted (Face × conv%) − Written off (Face × haircut%).
A14: Capital Structure | B14: 2_Capital_Structure_Waterfall!D52 | C14: Spectrum cash = IF(yr ≤ moratorium, IF(Cash mode, interest, 0 [PIK]), contractual instalment × (1 − conv%)).
A15: Capital Structure | B15: 2_Capital_Structure_Waterfall!$B$39 | C15: Govt stake = (existing Govt shares + conversion shares) / post-deal shares; excess over 49% → OCRPS.
... A44: Reconciliations | B44: 6_Reconciliations!$B$2 | C44: Snapshot date for the static tables R2-R6.

Sheet 6_Reconciliations
A1: 6. RECONCILIATIONS, SNAPSHOTS & CHANGE LOG (live formulas in black; static run snapshots in blue — regenerate by toggling the switches named in each block)
A2: Snapshot date for static tables R2–R6 (v3 build): | B2: 46301
A3: R1. CLAIMS — why Control Panel B65 and the liquidation waterfall B37 differ and both are right (v3: ≈ ₹2.51 trn vs ≈ ₹2.54 trn; the v1/v2 memo figures ₹2.48 trn / ₹2.66 trn pre-date the Q1 FY27 DPO update and counted the ₹15k cr SBI facility)
A4: Total claims — nominal, AGR at face (v3 ≈ ₹2.51 trn; memo: "₹2.48 trn") | B4: ='0_Control_Panel'!B65 -> 250856 | J4: Control Panel B65
A5: + SBI-led facility assumed drawn before failure (only if 4_Liq B8 = 1; v3 default 0) | B5: ='4_Liquidation_Waterfall'!B27-'0_Control_Panel'!B28-'0_Control_Panel'!B29 -> 0 | J5: 4_Liq B27 less existing bank + NCD. Nil at the v3 default (4_Liq B8 = 0); a Plan-A construct when B8 = 1 — in a pure Plan B/C world this line is nil.
A6: + s.53(1)(a) CIRP & liquidation costs | B6: ='4_Liquidation_Waterfall'!B30 -> 2500 | J6: Priority cost, not a pre-existing claim
A7: + s.53(1)(c) employee wages (12 months) | B7: ='4_Liquidation_Waterfall'!B24 -> 700 | J7: May already sit inside "other liabilities" ₹22,000 cr — possible overlap
A8: + s.53(1)(b) workmen dues (24 months) | B8: ='4_Liquidation_Waterfall'!B23 -> 150 | J8: As above
A9: → Claims in the waterfall (v3 ≈ ₹2.54 trn; memo: "₹2.66 trn admitted claims", which included the SBI facility) | B9: =SUM(B4:B8) -> 254206
A10: Waterfall total (4_Liquidation_Waterfall B37) | B10: ='4_Liquidation_Waterfall'!B37 -> 254206
A11: Check (must be 0) | B11: =ROUND(B9-B10,2) -> 0
A12: Govt statutory dues as % of Control Panel B65 / of the waterfall total (B9) | B12: =('0_Control_Panel'!B25+'0_Control_Panel'!B26)/B4 -> 0.77472733 | C12: =('0_Control_Panel'!B25+'0_Control_Panel'!B26)/B9 -> 0.76451775 | J12: ="Both bases show the same thing: ~"&TEXT(C12,"0%")&"–"&TEXT(B12,"0%")&" of the stack is Govt dues; lenders are ~"&TEXT(C13,"0.0%")&"–"&TEXT(B13,"0.0%")&" ("&TEXT(('0_Control_Panel'!B28+'0_Control_Panel'!B29+'0_Control_Panel'!B58*'0_Control_Panel'!B83)/B9,"0.0%")&" if the new ₹15k cr facility is counted)." -> Both bases show the same thing: ~76%–77% of the stack is Govt dues; lenders are ~1.4%–1.4% (7.3% if the new ₹15k cr facility is counted).
A13: Bank + NCD (funded debt) as % of B65 / of the waterfall total (B9) | B13: =('0_Control_Panel'!B28+'0_Control_Panel'!B29)/B4 -> 0.013996077 | C13: =('0_Control_Panel'!B28+'0_Control_Panel'!B29)/B9 -> 0.013811633
A14: Secured financial creditors as counted in the waterfall (SBI facility only if 4_Liq B8 = 1), as % of the waterfall total (B9) | B14: ='4_Liquidation_Waterfall'!B27/B9 -> 0.013811633
A16: R2. EV RANGE — one construction for the exec summary AND the football field (v1 mixed three methods)
A17: Snapshot date: see B2 (06-Oct-2026, v3). Static snapshot of model runs (Plan A / Base ARPU / 5G on / levers on unless stated). Blue = pasted run output; regenerate by toggling the switches named in each block.
A18: Case (Plan A structure) | B18: EV — exit multiple | C18: EV — Gordon cross-check | D18: TV % of EV (exit) | E18: FY29 cash EBITDA | F18: Govt rec. — Strict | G18: Govt rec. — Middle | H18: Govt rec. — Conservative | I18: EV ÷ liquidation (exit)
A19: High ARPU 11% (mgmt plan) | B19: 149596.25 | C19: 113475.13 | D19: 0.88424428 | E19: 19909.682 | F19: 0.78542413 | G19: 0.72625101 | H19: 0.49213127 | I19: =B19/'4_Liquidation_Waterfall'!$G$18 -> 3.1818816 | J19: v1 football field plotted ±10% bands around the exit-multiple EV for four cases (e.g. High 135–165k around 149.6k) and Gordon↔exit only for Base. v2 plots Gordon↔exit for every case.
A20: Base ARPU 7% | B20: 108038.4 | C20: 65514.731 | D20: 0.9342138 | E20: 16612.812 | F20: 0.57158866 | G20: 0.51241554 | H20: 0.2782958 | I20: =B20/'4_Liquidation_Waterfall'!$G$18 -> 2.2979545
A21: Base, 5G capex phased (switch off) | B21: 126397.16 | C21: 108231.62 | D21: 0.81025513 | E21: 16881.804 | F21: 0.66605344 | G21: 0.60688032 | H21: 0.37276058 | I21: =B21/'4_Liquidation_Waterfall'!$G$18 -> 2.6884416
A22: Low ARPU 4% | B22: 80335.492 | C22: 33344.895 | D22: 0.99943275 | E22: 14295.806 | F22: 0.42904367 | G22: 0.36987055 | H22: 0.13575082 | I22: =B22/'4_Liquidation_Waterfall'!$G$18 -> 1.7087194 | J22: Gordon in the Low case (₹33.3 k) is BELOW liquidation mid (₹47.0k): the crossover is earlier than the v1 memo said, though Gordon applies a 4% perpetuity to FY31 FCF that still carries ₹12k growth-level capex (punitive).
A23: Downside: Low ARPU, no churn/opex levers (STRESS) | B23: 45361.068 | C23: -7355.5585 | D23: 1.1923328 | E23: 11493.75 | F23: 0.24908317 | G23: 0.18991005 | H23: 0 | I23: =B23/'4_Liquidation_Waterfall'!$G$18 -> 0.96482061
A24: Liquidation proceeds — low / mid / high (live) | B24: ='4_Liquidation_Waterfall'!C19 -> 33925.028 | C24: ='4_Liquidation_Waterfall'!G18 -> 47015.028 | D24: ='4_Liquidation_Waterfall'!E19 -> 60405.028
A25: Range used in corrected exec summary — exit-multiple EV, four standard cases (min / max) | B25: =MIN(B19:B22) -> 80335.492 | C25: =MAX(B19:B22) -> 149596.25
A26: Gordon cross-check, four standard cases (min / max) | B26: =MIN(C19:C22) -> 33344.895 | C26: =MAX(C19:C22) -> 113475.13
A27: Full span incl. downside, both methods (min / max) | B27: =MIN(B19:C23) -> -7355.5585 | C27: =MAX(B19:C23) -> 149596.25
A28: Live check — active-case EV (C121) vs snapshot Base row; valid only at Plan A / Base ARPU / 5G on / levers on | B28: =IF(AND('0_Control_Panel'!B11=2,'0_Control_Panel'!B9=1,'0_Control_Panel'!B17=1,'0_Control_Panel'!B18=1),IF(ABS('3_Restructuring_Projections'!C121-B20)<1,"OK","STALE"),"n/a (switches differ)") -> OK
A30: R3. LIQUIDITY — why DSCR is negative and obligations are 6.0x yet "no liquidity facility" is needed (ACTIVE plan, live)
A31: ₹ crore | B31: FY27E | C31: FY28E | D31: FY29E | E31: FY30E | F31: FY31E
A32: Cash EBITDA | B32: ='3_Restructuring_Projections'!D39 -> 11702.739 | C32: ='3_Restructuring_Projections'!E39 -> 13928.834 | D32: ='3_Restructuring_Projections'!F39 -> 16612.812 | E32: ='3_Restructuring_Projections'!G39 -> 19851.393 | F32: ='3_Restructuring_Projections'!H39 -> 23763.682
A33: Less: capex | B33: =-'3_Restructuring_Projections'!D61 -> -13000 | C33: =-'3_Restructuring_Projections'!E61 -> -15500 | D33: =-'3_Restructuring_Projections'!F61 -> -15500 | E33: =-'3_Restructuring_Projections'!G61 -> -12000 | F33: =-'3_Restructuring_Projections'!H61 -> -12000
A34: Cash EBITDA − capex (DSCR numerator) | B34: =B32+B33 -> -1297.2614 | C34: =C32+C33 -> -1571.1663 | D34: =D32+D33 -> 1112.8119 | E34: =E32+E33 -> 7851.3929 | F34: =F32+F33 -> 11763.682
A35: DoT cash paid (spectrum + AGR) | B35: ='3_Restructuring_Projections'!D92+'3_Restructuring_Projections'!D93 -> -93 | C35: ='3_Restructuring_Projections'!E92+'3_Restructuring_Projections'!E93 -> -93 | D35: ='3_Restructuring_Projections'!F92+'3_Restructuring_Projections'!F93 -> -93 | E35: ='3_Restructuring_Projections'!G92+'3_Restructuring_Projections'!G93 -> -93 | F35: ='3_Restructuring_Projections'!H92+'3_Restructuring_Projections'!H93 -> -14493
A36: New money in (equity + asset sale + SBI draw) | B36: ='3_Restructuring_Projections'!D97+'3_Restructuring_Projections'!D95 -> 30000 | C36: ='3_Restructuring_Projections'!E97+'3_Restructuring_Projections'!E95 -> 0 | D36: ='3_Restructuring_Projections'!F97+'3_Restructuring_Projections'!F95 -> 0 | E36: ='3_Restructuring_Projections'!G97+'3_Restructuring_Projections'!G95 -> 0 | F36: ='3_Restructuring_Projections'!H97+'3_Restructuring_Projections'!H95 -> 0
A37: Liquidity-facility draw required | B37: ='3_Restructuring_Projections'!D101 -> 0 | C37: ='3_Restructuring_Projections'!E101 -> 0 | D37: ='3_Restructuring_Projections'!F101 -> 0 | E37: ='3_Restructuring_Projections'!G101 -> 0 | F37: ='3_Restructuring_Projections'!H101 -> 0
A38: Closing cash | B38: ='3_Restructuring_Projections'!D102 -> 34359.927 | C38: ='3_Restructuring_Projections'!E102 -> 32601.485 | D38: ='3_Restructuring_Projections'!F102 -> 30904.686 | E38: ='3_Restructuring_Projections'!G102 -> 34609.981 | F38: ='3_Restructuring_Projections'!H102 -> 29115.598
A39: Headroom over ₹4,000 cr floor | B39: =B38-'3_Restructuring_Projections'!$B$100 -> 30359.927 | C39: =C38-'3_Restructuring_Projections'!$B$100 -> 28601.485 | D39: =D38-'3_Restructuring_Projections'!$B$100 -> 26904.686 | E39: =E38-'3_Restructuring_Projections'!$B$100 -> 30609.981 | F39: =F38-'3_Restructuring_Projections'!$B$100 -> 25115.598
A40: DSCR (x) | B40: ='3_Restructuring_Projections'!D110 -> -0.6351118 | C40: ='3_Restructuring_Projections'!E110 -> -0.77060293 | D40: ='3_Restructuring_Projections'!F110 -> 0.31478167 | E40: ='3_Restructuring_Projections'!G110 -> 2.3244487 | F40: ='3_Restructuring_Projections'!H110 -> 0.66762092
A41: Total obligations ÷ cash EBITDA — AGR at carrying value (as reported, x) | B41: ='3_Restructuring_Projections'!D109 -> 9.9681836 | C41: ='3_Restructuring_Projections'!E109 -> 9.1910738 | D41: ='3_Restructuring_Projections'!F109 -> 8.3391059 | E41: ='3_Restructuring_Projections'!G109 -> 7.2746676 | F41: ='3_Restructuring_Projections'!H109 -> 6.1399559
A42: Total obligations ÷ cash EBITDA — AGR at NOMINAL (x) | B42: =IFERROR(('3_Restructuring_Projections'!D107+'3_Restructuring_Projections'!D71+'2_Capital_Structure_Waterfall'!D62)/'3_Restructuring_Projections'!D39,0) -> 12.3146 | C42: =IFERROR(('3_Restructuring_Projections'!E107+'3_Restructuring_Projections'!E71+'2_Capital_Structure_Waterfall'!E62)/'3_Restructuring_Projections'!E39,0) -> 11.066907 | D42: =IFERROR(('3_Restructuring_Projections'!F107+'3_Restructuring_Projections'!F71+'2_Capital_Structure_Waterfall'!F62)/'3_Restructuring_Projections'!F39,0) -> 9.8268942 | E42: =IFERROR(('3_Restructuring_Projections'!G107+'3_Restructuring_Projections'!G71+'2_Capital_Structure_Waterfall'!G62)/'3_Restructuring_Projections'!G39,0) -> 8.4442985 | F42: =IFERROR(('3_Restructuring_Projections'!H107+'3_Restructuring_Projections'!H71+'2_Capital_Structure_Waterfall'!H62)/'3_Restructuring_Projections'!H39,0) -> 7.0501668
...
